Workbook

Sheet porovnanie_vsetky_projekty
A1: Porovnanie projektov vystavby BD: BOB vs HMBA
A2: Porovnanie investicie cez BOB a priamo cez HMBA
A4: Vysledky za konsolidovany celok HMBA
A5: Projekt | B5: Cisty cashflow BOB | C5: Cisty cashflow HMBA | D5: Relativna vyhodnost BOB | E5: ROI BOB | F5: ROI HMBA
A6: BD Zitavska | B6: =zitavska_porovnanie!$B$22 -> 764430.61 | C6: =zitavska_porovnanie!$C$22 -> 145649.12 | D6: =zitavska_porovnanie!$C$23 -> 618781.49 | E6: =zitavska_porovnanie!$B$24 -> 0.16543639 | F6: =zitavska_porovnanie!$C$24 -> 0.026013216
A7: BD Antolska | B7: =antolska_porovnanie!$B$22 -> -2943683.7 | C7: =antolska_porovnanie!$C$22 -> -4288881.6 | D7: =antolska_porovnanie!$C$23 -> 1345197.9 | E7: =antolska_porovnanie!$B$24 -> -0.20928201 | F7: =antolska_porovnanie!$C$24 -> -0.2467279
A8: BD Na Vratkach | B8: =navratkach_porovnanie!$B$22 -> 2839222.9 | C8: =navratkach_porovnanie!$C$22 -> -2743242.7 | D8: =navratkach_porovnanie!$C$23 -> 5582465.6 | E8: =navratkach_porovnanie!$B$24 -> 0.062608224 | F8: =navratkach_porovnanie!$C$24 -> -0.049752802
A9: Spolu | B9: =SUM(B6:B8) -> 659969.84 | C9: =SUM(C6:C8) -> -6886475.2 | D9: =SUM(D6:D8) -> 7546445

Sheet zitavska_porovnanie
A1: Vystavba BD Zitavska
A2: Porovnanie investicie cez BOB a priamo cez HMBA
A4: Vysledok za konsolidovany celok HMBA
A5: Sucasne hodnoty financnych tokov | B5: Model BOB | C5: Model HMBA
A6: Vydavky | B6: =B7+B8 -> -6022494.4 | C6: =C7+C8 -> -7128346.6
A7: CAPEX (vystavba + udrzba) | B7: =zitavska_BOB!D21+zitavska_BOB!D22 -> -4620692 | C7: =zitavska_HMBA!D21+zitavska_HMBA!D22 -> -5599043.1
A8: OPEX (udrba + overhead) | B8: =zitavska_BOB!D62+zitavska_BOB!D63 -> -1401802.3 | C8: =zitavska_HMBA!D62+zitavska_HMBA!D63 -> -1529303.5
A9: Prijmy | B9: =B10+B11+B12 -> 4611320.9 | C9: =C10+C11+C12 -> 4917658.1
A10: Cisty prijem z najomneho | B10: =SUM(zitavska_BOB!D27:D28) -> 4917658.1 | C10: =SUM(zitavska_HMBA!D27:D28) -> 4917658.1
A11: Cisty financny tok z kupy bytov (HMBA od BOB) | B11: =zitavska_BOB!D38+zitavska_BOB!D39 -> -236247.13 | C11: 0
A12: Cisty financny tok z poplatku za spravu (HMBA pre BOB) | B12: =zitavska_BOB!D61+zitavska_BOB!D60 -> -70090.115 | C12: 0
A13: Financovanie | B13: =B14+B15+B16+B17 -> 2201569.9 | C13: =SUM(C14:C17) -> 2356337.7
A14: Dotacia a uver SFRB | B14: =zitavska_BOB!D35+zitavska_BOB!D36 -> 3569711.5 | C14: =zitavska_HMBA!D36+zitavska_HMBA!D35 -> 3472355.8
A15: Uvery (bullet aj dlhodoby uver HMBA) | B15: =zitavska_BOB!D34+zitavska_BOB!D37 -> 6623529.4 | C15: =zitavska_HMBA!D34+zitavska_HMBA!D37 -> 1623798.1
A16: Splatky komercnych uverov/uveru HMBA | B16: =zitavska_BOB!D44+zitavska_BOB!D46+zitavska_BOB!D45 -> -6844362.7 | C16: =zitavska_HMBA!D44+zitavska_HMBA!D45+zitavska_HMBA!D46 -> -1623798.1
A17: Splatka SFRB uveru | B17: =zitavska_BOB!D47+zitavska_BOB!D48 -> -1147308.3 | C17: =zitavska_HMBA!D47+zitavska_HMBA!D48 -> -1116018.1
A18: DPH | B18: =SUM(B19:B20) -> -25965.756 | C18: =SUM(C19:C20) -> 0
A19: DPH na vstupe/vystupe | B19: =zitavska_BOB!D24+zitavska_BOB!D40+zitavska_BOB!D64+zitavska_BOB!D65 -> -699731.47 | C19: 0
A20: Vratky DPH | B20: =zitavska_BOB!D51+zitavska_BOB!D66 -> 673765.71 | C20: 0
A22: Cisty financny tok (BOB+HMBA) | B22: =B6+B9+B13+B18 -> 764430.61 | C22: =C6+C9+C13+C18 -> 145649.12
A23: Relativna vyhodnost BOB oproti HMBA | C23: =B22-C22 -> 618781.49
A24: ROI | B24: =-B22/B7 -> 0.16543639 | C24: =-C22/C7 -> 0.026013216

Sheet zitavska_BOB
A1: Genericky investicny CF model
A2: Na jednom harku aby sa dal lahko kopirovat
A4: Predpoklady
A5: Nazov projektu | B5: Zitavska | D5: Pocet bytov (najomne byvanie) | E5: 34 | G5: Urokova sadzba SFRB | H5: 0.01 | J5: Urokova sadzba HMBA | K5: 0.04
A6: Stavebne naklady s DPH | B6: -5300000 | D6: Rozloha bytov (najomne byvanie) | E6: 1875 | G6: Maturita SFRB (roky) | H6: 40 | J6: Maturita HMBA (roky) | K6: 25
A7: Aplikovana sadzba DPH pre stavebne naklady | B7: 0.23 | D7: Jednotkove naklady bez DPH (eur/m2) | E7: =B8/E6 -> -2298.103 | G7: Podiel dotacie/SFRB | H7: 0.4 | J7: Urokova sadzba BOB | K7: 0.06
A8: Stavebne naklady bez DPH | B8: =B6/(1+$B$7) -> -4308943.1 | D8: Podiel bytov vhodnych na dotaciu/SFRB | E8: 1 | G8: Dotacny strop na m2 BOB | H8: 1980 | J8: Maturita BOB (roky, prevadzka) | K8: 25
A9: NFA (m2) | B9: 2663 | G9: Dotacny strop na m2 HMBA | H9: 2140
A11: DPH pre BOB | B11: 0.05 | D11: Najomne bytov/mesiac/m2 | E11: 7 | G11: SFRB+dotacia HMBA model | H11: =MIN(H9,-$E$7)*$E$6*0.9 -> 3611250 | J11: Frekvencia CAPEX obnovy | K11: 10 | M11: Potreba uveru HMBA (HMBA model) | N11: =-B8*(1+$B$12)-H11 -> 1688750
A12: DPH pre HMBA | B12: 0.23 | D12: Najomne nebytov/mesiac/m2 | E12: 2.5 | G12: SFRB+dotacia BOB model | H12: =MIN(H8,-$E$7)*$E$6 -> 3712500 | J12: Percento CAPEX obnovy | K12: 0.05 | M12: Potreba uveru HMBA (BOB model) | N12: =N13-H12 -> 1447137.3
A13: Indexacia najomneho p.a. | B13: 0.02 | D13: Fond oprav mesiac/m2 | E13: 1.5 | G13: Prijem z najomneho 1. rok (vratane fondu oprav, byty) | H13: =(E11+E13)*E6*12 -> 191250 | J13: Tvorba fondu na CAPEX opravy | K13: 0.007 | M13: Kupna cena od BOBu | N13: =(-SUM(E44:AL44)+SUMIFS(E24:AL24,E18:AL18,">0"))*(1+B11)*(1+K14) -> 5159637.3
A14: Trvanie vystavby (roky) | B14: 1.5 | D14: Naklady na spravu a prevadkzu s DPH (/m2/rok) | E14: -11.3 | G14: Prijem z najomneho 1. rok (vratane fondu oprav, nebyty) | H14: =(B9-E6)*E12*12 -> 23640 | J14: Ziskova marza pre BOB | K14: 0.05 | M14: Overhead OPEX pre BOB / byt | N14: -1100
A16: Cashflow
A18: Fazovanie vystavby | E18: =IF(E$19<=ROUNDDOWN($B$14,0),(ROUNDDOWN($B$14,0)/$B$14)/ROUNDDOWN($B$14,0),IF(E$19=ROUNDUP($B$14,0),1-SUM($D$18:D18),0)) -> 0.66666667 | F18: =IF(F$19<=ROUNDDOWN($B$14,0),(ROUNDDOWN($B$14,0)/$B$14)/ROUNDDOWN($B$14,0),IF(F$19=ROUNDUP($B$14,0),1-SUM($D$18:E18),0)) -> 0.33333333 | G18: =IF(G$19<=ROUNDDOWN($B$14,0),(ROUNDDOWN($B$14,0)/$B$14)/ROUNDDOWN($B$14,0),IF(G$19=ROUNDUP($B$14,0),1-SUM($D$18:F18),0)) -> 0 | H18: =IF(H$19<=ROUNDDOWN($B$14,0),(ROUNDDOWN($B$14,0)/$B$14)/ROUNDDOWN($B$14,0),IF(H$19=ROUNDUP($B$14,0),1-SUM($D$18:G18),0)) -> 0 | I18: =IF(I$19<=ROUNDDOWN($B$14,0),(ROUNDDOWN($B$14,0)/$B$14)/ROUNDDOWN($B$14,0),IF(I$19=ROUNDUP($B$14,0),1-SUM($D$18:H18),0)) -> 0 | J18: =IF(J$19<=ROUNDDOWN($B$14,0),(ROUNDDOWN($B$14,0)/$B$14)/ROUNDDOWN($B$14,0),IF(J$19=ROUNDUP($B$14,0),1-SUM($D$18:I18),0)) -> 0 | K18: =IF(K$19<=ROUNDDOWN($B$14,0),(ROUNDDOWN($B$14,0)/$B$14)/ROUNDDOWN($B$14,0),IF(K$19=ROUNDUP($B$14,0),1-SUM($D$18:J18),0)) -> 0 | L18: =IF(L$19<=ROUNDDOWN($B$14,0),(ROUNDDOWN($B$14,0)/$B$14)/ROUNDDOWN($B$14,0),IF(L$19=ROUNDUP($B$14,0),1-SUM($D$18:K18),0)) -> 0 | M18: =IF(M$19<=ROUNDDOWN($B$14,0),(ROUNDDOWN($B$14,0)/$B$14)/ROUNDDOWN($B$14,0),IF(M$19=ROUNDUP($B$14,0),1-SUM($D$18:L18),0)) -> 0
A19: Polozka | B19: Vlastnik polozky | C19: DPH | D19: PV | E19: 1 | F19: 2 | G19: 3 | H19: 4 | I19: 5 | J19: 6 | K19: 7 | L19: 8 | M19: 9 | N19: 10 | O19: 11 | P19: 12 | Q19: 13 | R19: 14 | S19: 15 | T19: 16 | U19: 17 | V19: 18 | W19: 19 | X19: 20 | Y19: 21 | Z19: 22 | AA19: 23 | AB19: 24 | AC19: 25 | AD19: 26 | AE19: 27 | AF19: 28 | AG19: 29 | AH19: 30 | AI19: 31 | AJ19: 32 | AK19: 33 | AL19: 34
A20: Naklady bez DPH
A21: CAPEX vystavba | B21: BOB | C21: TRUE | D21: =E21+NPV($K$5,F21:AK21) -> -4253700.2 | E21: =$B$8*E$18 -> -2872628.7 | F21: =$B$8*F$18 -> -1436314.4 | G21: =$B$8*G$18 -> 0 | H21: =$B$8*H$18 -> 0 | I21: =$B$8*I$18 -> 0 | J21: =$B$8*J$18 -> 0 | K21: =$B$8*K$18 -> 0 | L21: =$B$8*L$18 -> 0 | ... AL21: =$B$8*AL$18 -> 0
A22: CAPEX obnova | B22: HMBA | C22: FALSE | D22: =E22+NPV($K$5,F22:AK22) -> -366991.82 | E22: =IF(E$19<($K$11+ROUNDUP($B$14,0)),0,IF(MOD(E$19-ROUNDUP($B$14,0),$K$11)=0,$B$6*$K$12*POWER(1+$B$13,E$19-ROUNDUP(E$19,0)),0)) -> 0 | F22: =IF(F$19<($K$11+ROUNDUP($B$14,0)),0,IF(MOD(F$19-ROUNDUP($B$14,0),$K$11)=0,$B$6*$K$12*POWER(1+$B$13,F$19-ROUNDUP(F$19,0)),0)) -> 0 | G22: =IF(G$19<($K$11+ROUNDUP($B$14,0)),0,IF(MOD(G$19-ROUNDUP($B$14,0),$K$11)=0,$B$6*$K$12*POWER(1+$B$13,G$19-ROUNDUP(G$19,0)),0)) -> 0 | H22: =IF(H$19<($K$11+ROUNDUP($B$14,0)),0,IF(MOD(H$19-ROUNDUP($B$14,0),$K$11)=0,$B$6*$K$12*POWER(1+$B$13,H$19-ROUNDUP(H$19,0)),0)) -> 0 | I22: =IF(I$19<($K$11+ROUNDUP($B$14,0)),0,IF(MOD(I$19-ROUNDUP($B$14,0),$K$11)=0,$B$6*$K$12*POWER(1+$B$13,I$19-ROUNDUP(I$19,0)),0)) -> 0 | J22: =IF(J$19<($K$11+ROUNDUP($B$14,0)),0,IF(MOD(J$19-ROUNDUP($B$14,0),$K$11)=0,$B$6*$K$12*POWER(1+$B$13,J$19-ROUNDUP(J$19,0)),0)) -> 0 | K22: =IF(K$19<($K$11+ROUNDUP($B$14,0)),0,IF(MOD(K$19-ROUNDUP($B$14,0),$K$11)=0,$B$6*$K$12*POWER(1+$B$13,K$19-ROUNDUP(K$19,0)),0)) -> 0 | L22: =IF(L$19<($K$11+ROUNDUP($B$14,0)),0,IF(MOD(L$19-ROUNDUP($B$14,0),$K$11)=0,$B$6*$K$12*POWER(1+$B$13,L$19-ROUNDUP(L$19,0)),0)) -> 0 | ... AL22: =IF(AL$19<($K$11+ROUNDUP($B$14,0)),0,IF(MOD(AL$19-ROUNDUP($B$14,0),$K$11)=0,$B$6*$K$12*POWER(1+$B$13,AL$19-ROUNDUP(AL$19,0)),0)) -> 0
A24: DPH na vstupe | B24: BOB | D24: =E24+NPV($K$5,F24:AK24) -> -978351.05 | E24: =SUMIFS(E$21:E$23,$C$21:$C$23,TRUE)*$B$12 -> -660704.61 | F24: =SUMIFS(F$21:F$23,$C$21:$C$23,TRUE)*$B$12 -> -330352.3 | G24: =SUMIFS(G$21:G$23,$C$21:$C$23,TRUE)*$B$12 -> 0 | H24: =SUMIFS(H$21:H$23,$C$21:$C$23,TRUE)*$B$12 -> 0 | I24: =SUMIFS(I$21:I$23,$C$21:$C$23,TRUE)*$B$12 -> 0 | J24: =SUMIFS(J$21:J$23,$C$21:$C$23,TRUE)*$B$12 -> 0 | K24: =SUMIFS(K$21:K$23,$C$21:$C$23,TRUE)*$B$12 -> 0 | L24: =SUMIFS(L$21:L$23,$C$21:$C$23,TRUE)*$B$12 -> 0 | ... AL24: =SUMIFS(AL$21:AL$23,$C$21:$C$23,TRUE)*$B$12 -> 0
A26: Najomne a fond oprav
A27: Prijem z najomneho byty | B27: HMBA | C27: FALSE | D27: =E27+NPV($K$5,F27:AK27) -> 4376667.6 | E27: =IF(E19>$B$14,$H$13*POWER(1+$B$13,E$19-$B$14),0)*(1-(($B$14-ROUNDDOWN($B$14,0))*IF(E$19=ROUNDUP($B$14,0),1,0))) -> 0 | F27: =IF(F19>$B$14,$H$13*POWER(1+$B$13,F$19-$B$14),0)*(1-(($B$14-ROUNDDOWN($B$14,0))*IF(F$19=ROUNDUP($B$14,0),1,0))) -> 96576.516 | G27: =IF(G19>$B$14,$H$13*POWER(1+$B$13,G$19-$B$14),0)*(1-(($B$14-ROUNDDOWN($B$14,0))*IF(G$19=ROUNDUP($B$14,0),1,0))) -> 197016.09 | H27: =IF(H19>$B$14,$H$13*POWER(1+$B$13,H$19-$B$14),0)*(1-(($B$14-ROUNDDOWN($B$14,0))*IF(H$19=ROUNDUP($B$14,0),1,0))) -> 200956.41 | I27: =IF(I19>$B$14,$H$13*POWER(1+$B$13,I$19-$B$14),0)*(1-(($B$14-ROUNDDOWN($B$14,0))*IF(I$19=ROUNDUP($B$14,0),1,0))) -> 204975.54 | J27: =IF(J19>$B$14,$H$13*POWER(1+$B$13,J$19-$B$14),0)*(1-(($B$14-ROUNDDOWN($B$14,0))*IF(J$19=ROUNDUP($B$14,0),1,0))) -> 209075.05 | K27: =IF(K19>$B$14,$H$13*POWER(1+$B$13,K$19-$B$14),0)*(1-(($B$14-ROUNDDOWN($B$14,0))*IF(K$19=ROUNDUP($B$14,0),1,0))) -> 213256.55 | L27: =IF(L19>$B$14,$H$13*POWER(1+$B$13,L$19-$B$14),0)*(1-(($B$14-ROUNDDOWN($B$14,0))*IF(L$19=ROUNDUP($B$14,0),1,0))) -> 217521.69 | ... AL27: =IF(AL19>$B$14,$H$13*POWER(1+$B$13,AL$19-$B$14),0)*(1-(($B$14-ROUNDDOWN($B$14,0))*IF(AL$19=ROUNDUP($B$14,0),1,0))) -> 364004.73
A28: Prijem z najomneho nebyty | B28: HMBA | C28: FALSE | D28: =E28+NPV($K$5,F28:AK28) -> 540990.45 | E28: =IF(E19>$B$14,$H$14*POWER(1+$B$13,E$19-$B$14),0)*(1-(($B$14-ROUNDDOWN($B$14,0))*IF(E$19=ROUNDUP($B$14,0),1,0))) -> 0 | F28: =IF(F19>$B$14,$H$14*POWER(1+$B$13,F$19-$B$14),0)*(1-(($B$14-ROUNDDOWN($B$14,0))*IF(F$19=ROUNDUP($B$14,0),1,0))) -> 11937.615 | G28: =IF(G19>$B$14,$H$14*POWER(1+$B$13,G$19-$B$14),0)*(1-(($B$14-ROUNDDOWN($B$14,0))*IF(G$19=ROUNDUP($B$14,0),1,0))) -> 24352.734 | H28: =IF(H19>$B$14,$H$14*POWER(1+$B$13,H$19-$B$14),0)*(1-(($B$14-ROUNDDOWN($B$14,0))*IF(H$19=ROUNDUP($B$14,0),1,0))) -> 24839.789 | I28: =IF(I19>$B$14,$H$14*POWER(1+$B$13,I$19-$B$14),0)*(1-(($B$14-ROUNDDOWN($B$14,0))*IF(I$19=ROUNDUP($B$14,0),1,0))) -> 25336.585 | J28: =IF(J19>$B$14,$H$14*POWER(1+$B$13,J$19-$B$14),0)*(1-(($B$14-ROUNDDOWN($B$14,0))*IF(J$19=ROUNDUP($B$14,0),1,0))) -> 25843.316 | K28: =IF(K19>$B$14,$H$14*POWER(1+$B$13,K$19-$B$14),0)*(1-(($B$14-ROUNDDOWN($B$14,0))*IF(K$19=ROUNDUP($B$14,0),1,0))) -> 26360.183 | L28: =IF(L19>$B$14,$H$14*POWER(1+$B$13,L$19-$B$14),0)*(1-(($B$14-ROUNDDOWN($B$14,0))*IF(L$19=ROUNDUP($B$14,0),1,0))) -> 26887.386 | ... AL28: =IF(AL19>$B$14,$H$14*POWER(1+$B$13,AL$19-$B$14),0)*(1-(($B$14-ROUNDDOWN($B$14,0))*IF(AL$19=ROUNDUP($B$14,0),1,0))) -> 44993.839
A29: Tvorba fondu oprav na CAPEX | C29: FALSE | D29: =E29+NPV($K$5,F29:AK29) -> -867030.33 | E29: =IF(E27>0,$B$6*$K$13*POWER(1+$B$13,E$19-$B$14),0) -> 0 | F29: =IF(F27>0,$B$6*$K$13*POWER(1+$B$13,F$19-$B$14),0) -> -37469.163 | G29: =IF(G27>0,$B$6*$K$13*POWER(1+$B$13,G$19-$B$14),0) -> -38218.547 | H29: =IF(H27>0,$B$6*$K$13*POWER(1+$B$13,H$19-$B$14),0) -> -38982.918 | I29: =IF(I27>0,$B$6*$K$13*POWER(1+$B$13,I$19-$B$14),0) -> -39762.576 | J29: =IF(J27>0,$B$6*$K$13*POWER(1+$B$13,J$19-$B$14),0) -> -40557.827 | K29: =IF(K27>0,$B$6*$K$13*POWER(1+$B$13,K$19-$B$14),0) -> -41368.984 | L29: =IF(L27>0,$B$6*$K$13*POWER(1+$B$13,L$19-$B$14),0) -> -42196.364 | ... AL29: =IF(AL27>0,$B$6*$K$13*POWER(1+$B$13,AL$19-$B$14),0) -> -70612.159
A30: Cerpanie fondu oprav na CAPEX | C30: FALSE | D30: =E30+NPV($K$5,F30:AK30) -> 366991.82 | E30: =-E22 -> 0 | F30: =-F22 -> 0 | G30: =-G22 -> 0 | H30: =-H22 -> 0 | I30: =-I22 -> 0 | J30: =-J22 -> 0 | K30: =-K22 -> 0 | L30: =-L22 -> 0 | ... AL30: =-AL22 -> 0
A31: Zostatok fondu oprav na CAPEX | E31: 0 | F31: =E31-F29-F30 -> 37469.163 | G31: =F31-G29-G30 -> 75687.71 | H31: =G31-H29-H30 -> 114670.63 | I31: =H31-I29-I30 -> 154433.2 | J31: =I31-J29-J30 -> 194991.03 | K31: =J31-K29-K30 -> 236360.01 | L31: =K31-L29-L30 -> 278556.38 | M31: =L31-M29-M30 -> 321596.67 | ... AL31: =AK31-AL29-AL30 -> 932761.95
A33: Financovanie
A34: Cerpanie komercneho uveru (bullet) | B34: BOB | C34: FALSE | D34: =E34+NPV($K$5,F34:AK34) -> 5232051.3 | E34: =IF(E18>0,-E21-E24,0) -> 3533333.3 | F34: =IF(F18>0,-F21-F24,0) -> 1766666.7 | G34: =IF(G18>0,-G21-G24,0) -> 0 | H34: =IF(H18>0,-H21-H24,0) -> 0 | I34: =IF(I18>0,-I21-I24,0) -> 0 | J34: =IF(J18>0,-J21-J24,0) -> 0 | K34: =IF(K18>0,-K21-K24,0) -> 0 | L34: =IF(L18>0,-L21-L24,0) -> 0 | ... AL34: =IF(AL18>0,-AL21-AL24,0) -> 0
A35: Dotacia SFRB | B35: HMBA | C35: FALSE | D35: =E35+NPV($K$5,F35:AK35) -> 1427884.6 | E35: =IF(E$19=ROUNDUP($B$14,0),$H$12*$H$7,0) -> 0 | F35: =IF(F$19=ROUNDUP($B$14,0),$H$12*$H$7,0) -> 1485000 | G35: =IF(G$19=ROUNDUP($B$14,0),$H$12*$H$7,0) -> 0 | H35: =IF(H$19=ROUNDUP($B$14,0),$H$12*$H$7,0) -> 0 | I35: =IF(I$19=ROUNDUP($B$14,0),$H$12*$H$7,0) -> 0 | J35: =IF(J$19=ROUNDUP($B$14,0),$H$12*$H$7,0) -> 0 | K35: =IF(K$19=ROUNDUP($B$14,0),$H$12*$H$7,0) -> 0 | L35: =IF(L$19=ROUNDUP($B$14,0),$H$12*$H$7,0) -> 0 | ... AL35: =IF(AL$19=ROUNDUP($B$14,0),$H$12*$H$7,0) -> 0
A36: Uver SFRB | B36: HMBA | C36: FALSE | D36: =E36+NPV($K$5,F36:AK36) -> 2141826.9 | E36: =IF(E$19=ROUNDUP($B$14,0),$H$12*(1-$H$7),0) -> 0 | F36: =IF(F$19=ROUNDUP($B$14,0),$H$12*(1-$H$7),0) -> 2227500 | G36: =IF(G$19=ROUNDUP($B$14,0),$H$12*(1-$H$7),0) -> 0 | H36: =IF(H$19=ROUNDUP($B$14,0),$H$12*(1-$H$7),0) -> 0 | I36: =IF(I$19=ROUNDUP($B$14,0),$H$12*(1-$H$7),0) -> 0 | J36: =IF(J$19=ROUNDUP($B$14,0),$H$12*(1-$H$7),0) -> 0 | K36: =IF(K$19=ROUNDUP($B$14,0),$H$12*(1-$H$7),0) -> 0 | L36: =IF(L$19=ROUNDUP($B$14,0),$H$12*(1-$H$7),0) -> 0 | ... AL36: =IF(AL$19=ROUNDUP($B$14,0),$H$12*(1-$H$7),0) -> 0
A37: Uver HMBA | B37: HMBA | C37: FALSE | D37: =E37+NPV($K$5,F37:AK37) -> 1391478.1 | E37: =IF(E$19=ROUNDUP($B$14,0),$N$12,0) -> 0 | F37: =IF(F$19=ROUNDUP($B$14,0),$N$12,0) -> 1447137.3 | G37: =IF(G$19=ROUNDUP($B$14,0),$N$12,0) -> 0 | H37: =IF(H$19=ROUNDUP($B$14,0),$N$12,0) -> 0 | I37: =IF(I$19=ROUNDUP($B$14,0),$N$12,0) -> 0 | J37: =IF(J$19=ROUNDUP($B$14,0),$N$12,0) -> 0 | K37: =IF(K$19=ROUNDUP($B$14,0),$N$12,0) -> 0 | L37: =IF(L$19=ROUNDUP($B$14,0),$N$12,0) -> 0 | ... AL37: =IF(AL$19=ROUNDUP($B$14,0),$N$12,0) -> 0
A38: Kupa bytov do vlastnictva HMBA | B38: HMBA | C38: FALSE | D38: =E38+NPV($K$5,F38:AK38) -> -4961189.7 | E38: =IF(E$19=ROUNDUP($B$14,0),-$H$12-$N$12,0) -> 0 | F38: =IF(F$19=ROUNDUP($B$14,0),-$H$12-$N$12,0) -> -5159637.3 | G38: =IF(G$19=ROUNDUP($B$14,0),-$H$12-$N$12,0) -> 0 | H38: =IF(H$19=ROUNDUP($B$14,0),-$H$12-$N$12,0) -> 0 | I38: =IF(I$19=ROUNDUP($B$14,0),-$H$12-$N$12,0) -> 0 | J38: =IF(J$19=ROUNDUP($B$14,0),-$H$12-$N$12,0) -> 0 | K38: =IF(K$19=ROUNDUP($B$14,0),-$H$12-$N$12,0) -> 0 | L38: =IF(L$19=ROUNDUP($B$14,0),-$H$12-$N$12,0) -> 0 | ... AL38: =IF(AL$19=ROUNDUP($B$14,0),-$H$12-$N$12,0) -> 0
A39: Prijem z predaja bytov | B39: BOB | C39: TRUE | D39: =E39+NPV($K$5,F39:AK39) -> 4724942.5 | E39: =-E38/(1+$B$11) -> 0 | F39: =-F38/(1+$B$11) -> 4913940.2 | G39: =-G38/(1+$B$11) -> 0 | H39: =-H38/(1+$B$11) -> 0 | I39: =-I38/(1+$B$11) -> 0 | J39: =-J38/(1+$B$11) -> 0 | K39: =-K38/(1+$B$11) -> 0 | L39: =-L38/(1+$B$11) -> 0 | ... AL39: =-AL38/(1+$B$11) -> 0
A40: DPH na vystupe | B40: BOB | D40: =E40+NPV($K$5,F40:AK40) -> 236247.13 | E40: =SUMIFS(E$34:E$39,$C$34:$C$39,TRUE)*$B$11 -> 0 | F40: =SUMIFS(F$34:F$39,$C$34:$C$39,TRUE)*$B$11 -> 245697.01 | G40: =SUMIFS(G$34:G$39,$C$34:$C$39,TRUE)*$B$11 -> 0 | H40: =SUMIFS(H$34:H$39,$C$34:$C$39,TRUE)*$B$11 -> 0 | I40: =SUMIFS(I$34:I$39,$C$34:$C$39,TRUE)*$B$11 -> 0 | J40: =SUMIFS(J$34:J$39,$C$34:$C$39,TRUE)*$B$11 -> 0 | K40: =SUMIFS(K$34:K$39,$C$34:$C$39,TRUE)*$B$11 -> 0 | L40: =SUMIFS(L$34:L$39,$C$34:$C$39,TRUE)*$B$11 -> 0 | ... AL40: =SUMIFS(AL$34:AL$39,$C$34:$C$39,TRUE)*$B$11 -> 0
A42: Dlhova sluzba
A43: Kapitalizacia urokov komercneho uveru | B43: FALSE | C43: FALSE | E43: =E34*0.5*$K$7*IF(E18=0,0,1) -> 106000 | F43: =(SUM($E$34:E34)+F34*0.5)*$K$7*IF(F18=0,0,1) -> 265000 | G43: =(SUM($E$34:F34)+G34*0.5)*$K$7*IF(G18=0,0,1) -> 0 | H43: =(SUM($E$34:G34)+H34*0.5)*$K$7*IF(H18=0,0,1) -> 0 | I43: =(SUM($E$34:H34)+I34*0.5)*$K$7*IF(I18=0,0,1) -> 0 | J43: =(SUM($E$34:I34)+J34*0.5)*$K$7*IF(J18=0,0,1) -> 0 | K43: =(SUM($E$34:J34)+K34*0.5)*$K$7*IF(K18=0,0,1) -> 0 | L43: =(SUM($E$34:K34)+L34*0.5)*$K$7*IF(L18=0,0,1) -> 0 | M43: =(SUM($E$34:L34)+M34*0.5)*$K$7*IF(M18=0,0,1) -> 0 | ... AL43: =(SUM($E$34:AK34)+AL34*0.5)*$K$7*IF(AL18=0,0,1) -> 0
A44: Splatka komercneho uveru | B44: BOB | C44: FALSE | D44: =E44+NPV($K$5,F44:AK44) -> -5452884.6 | E44: =-IF(E19=ROUNDUP($B$14,0),SUM($E$34:$AL$34,$E$43:$AL$43),0) -> 0 | F44: =-IF(F19=ROUNDUP($B$14,0),SUM($E$34:$AL$34,$E$43:$AL$43),0) -> -5671000 | G44: =-IF(G19=ROUNDUP($B$14,0),SUM($E$34:$AL$34,$E$43:$AL$43),0) -> 0 | H44: =-IF(H19=ROUNDUP($B$14,0),SUM($E$34:$AL$34,$E$43:$AL$43),0) -> 0 | I44: =-IF(I19=ROUNDUP($B$14,0),SUM($E$34:$AL$34,$E$43:$AL$43),0) -> 0 | J44: =-IF(J19=ROUNDUP($B$14,0),SUM($E$34:$AL$34,$E$43:$AL$43),0) -> 0 | K44: =-IF(K19=ROUNDUP($B$14,0),SUM($E$34:$AL$34,$E$43:$AL$43),0) -> 0 | L44: =-IF(L19=ROUNDUP($B$14,0),SUM($E$34:$AL$34,$E$43:$AL$43),0) -> 0 | ... AL44: =-IF(AL19=ROUNDUP($B$14,0),SUM($E$34:$AL$34,$E$43:$AL$43),0) -> 0
A45: Splatka uveru HMBA (istina) | B45: HMBA | C45: FALSE | D45: =E45+NPV($K$5,F45:AK45) -> -803175.97 | E45: =IF(E$19>ROUNDUP($B$14,0),IF(E46<>-0.01,PPMT($K$5,E$19-ROUNDUP($B$14,0),$K$6,$N$12),0.01),0) -> 0 | F45: =IF(F19>ROUNDUP($B$14,0),IF(F46<>-0.01,PPMT($K$5,F$19-ROUNDUP($B$14,0),$K$6,$N$12),0.01),0) -> 0 | G45: =IF(G19>ROUNDUP($B$14,0),IF(G46<>-0.01,PPMT($K$5,G$19-ROUNDUP($B$14,0),$K$6,$N$12),0.01),0) -> -34748.606 | H45: =IF(H19>ROUNDUP($B$14,0),IF(H46<>-0.01,PPMT($K$5,H$19-ROUNDUP($B$14,0),$K$6,$N$12),0.01),0) -> -36138.55 | I45: =IF(I19>ROUNDUP($B$14,0),IF(I46<>-0.01,PPMT($K$5,I$19-ROUNDUP($B$14,0),$K$6,$N$12),0.01),0) -> -37584.092 | J45: =IF(J19>ROUNDUP($B$14,0),IF(J46<>-0.01,PPMT($K$5,J$19-ROUNDUP($B$14,0),$K$6,$N$12),0.01),0) -> -39087.456 | K45: =IF(K19>ROUNDUP($B$14,0),IF(K46<>-0.01,PPMT($K$5,K$19-ROUNDUP($B$14,0),$K$6,$N$12),0.01),0) -> -40650.954 | L45: =IF(L19>ROUNDUP($B$14,0),IF(L46<>-0.01,PPMT($K$5,L$19-ROUNDUP($B$14,0),$K$6,$N$12),0.01),0) -> -42276.992 | M45: =IF(M19>ROUNDUP($B$14,0),IF(M46<>-0.01,PPMT($K$5,M$19-ROUNDUP($B$14,0),$K$6,$N$12),0.01),0) -> -43968.072 | ... AL45: =IF(AL19>ROUNDUP($B$14,0),IF(AL46<>-0.01,PPMT($K$5,AL$19-ROUNDUP($B$14,0),$K$6,$N$12),0.01),0) -> 0.01
A46: Splatka uveru HMBA (uroky) | B46: HMBA | C46: FALSE | D46: =E46+NPV($K$5,F46:AK46) -> -588302.16 | E46: =IF(E$19>ROUNDUP($B$14,0),IFERROR(IPMT($K$5,E$19-ROUNDUP($B$14,0),$K$6,$N$12),-0.01),0) -> 0 | F46: =IF(F$19>ROUNDUP($B$14,0),IFERROR(IPMT($K$5,F$19-ROUNDUP($B$14,0),$K$6,$N$12),-0.01),0) -> 0 | G46: =IF(G$19>ROUNDUP($B$14,0),IFERROR(IPMT($K$5,G$19-ROUNDUP($B$14,0),$K$6,$N$12),-0.01),0) -> -57885.49 | H46: =IF(H$19>ROUNDUP($B$14,0),IFERROR(IPMT($K$5,H$19-ROUNDUP($B$14,0),$K$6,$N$12),-0.01),0) -> -56495.546 | I46: =IF(I$19>ROUNDUP($B$14,0),IFERROR(IPMT($K$5,I$19-ROUNDUP($B$14,0),$K$6,$N$12),-0.01),0) -> -55050.004 | J46: =IF(J$19>ROUNDUP($B$14,0),IFERROR(IPMT($K$5,J$19-ROUNDUP($B$14,0),$K$6,$N$12),-0.01),0) -> -53546.64 | K46: =IF(K$19>ROUNDUP($B$14,0),IFERROR(IPMT($K$5,K$19-ROUNDUP($B$14,0),$K$6,$N$12),-0.01),0) -> -51983.142 | L46: =IF(L$19>ROUNDUP($B$14,0),IFERROR(IPMT($K$5,L$19-ROUNDUP($B$14,0),$K$6,$N$12),-0.01),0) -> -50357.104 | ... AL46: =IF(AL$19>ROUNDUP($B$14,0),IFERROR(IPMT($K$5,AL$19-ROUNDUP($B$14,0),$K$6,$N$12),-0.01),0) -> -0.01
A47: Splatka uveru SFRB (istina) | B47: HMBA | C47: FALSE | D47: =E47+NPV($K$5,F47:AK47) -> -871019.51 | E47: =IF(E$19>ROUNDUP($B$14,0),IF(E48<>-0.01,PPMT($H$5,E$19-ROUNDUP($B$14,0),$H$6,$H$12*(1-$H$7)),0.01),0) -> 0 | F47: =IF(F$19>ROUNDUP($B$14,0),IF(F48<>-0.01,PPMT($H$5,F$19-ROUNDUP($B$14,0),$H$6,$H$12*(1-$H$7)),0.01),0) -> 0 | G47: =IF(G$19>ROUNDUP($B$14,0),IF(G48<>-0.01,PPMT($H$5,G$19-ROUNDUP($B$14,0),$H$6,$H$12*(1-$H$7)),0.01),0) -> -45564.844 | H47: =IF(H$19>ROUNDUP($B$14,0),IF(H48<>-0.01,PPMT($H$5,H$19-ROUNDUP($B$14,0),$H$6,$H$12*(1-$H$7)),0.01),0) -> -46020.493 | I47: =IF(I$19>ROUNDUP($B$14,0),IF(I48<>-0.01,PPMT($H$5,I$19-ROUNDUP($B$14,0),$H$6,$H$12*(1-$H$7)),0.01),0) -> -46480.698 | J47: =IF(J$19>ROUNDUP($B$14,0),IF(J48<>-0.01,PPMT($H$5,J$19-ROUNDUP($B$14,0),$H$6,$H$12*(1-$H$7)),0.01),0) -> -46945.505 | K47: =IF(K$19>ROUNDUP($B$14,0),IF(K48<>-0.01,PPMT($H$5,K$19-ROUNDUP($B$14,0),$H$6,$H$12*(1-$H$7)),0.01),0) -> -47414.96 | L47: =IF(L$19>ROUNDUP($B$14,0),IF(L48<>-0.01,PPMT($H$5,L$19-ROUNDUP($B$14,0),$H$6,$H$12*(1-$H$7)),0.01),0) -> -47889.109 | ... AL47: =IF(AL$19>ROUNDUP($B$14,0),IF(AL48<>-0.01,PPMT($H$5,AL$19-ROUNDUP($B$14,0),$H$6,$H$12*(1-$H$7)),0.01),0) -> -62028.671
A48: Splatka uveru SFRB (uroky) | B48: HMBA | C48: FALSE | D48: =E48+NPV($K$5,F48:AK48) -> -276288.83 | E48: =IF(E$19>ROUNDUP($B$14,0),IFERROR(IPMT($H$5,E$19-ROUNDUP($B$14,0),$H$6,$H$12*(1-$H$7)),-0.01),0) -> 0 | F48: =IF(F$19>ROUNDUP($B$14,0),IFERROR(IPMT($H$5,F$19-ROUNDUP($B$14,0),$H$6,$H$12*(1-$H$7)),-0.01),0) -> 0 | G48: =IF(G$19>ROUNDUP($B$14,0),IFERROR(IPMT($H$5,G$19-ROUNDUP($B$14,0),$H$6,$H$12*(1-$H$7)),-0.01),0) -> -22275 | H48: =IF(H$19>ROUNDUP($B$14,0),IFERROR(IPMT($H$5,H$19-ROUNDUP($B$14,0),$H$6,$H$12*(1-$H$7)),-0.01),0) -> -21819.352 | I48: =IF(I$19>ROUNDUP($B$14,0),IFERROR(IPMT($H$5,I$19-ROUNDUP($B$14,0),$H$6,$H$12*(1-$H$7)),-0.01),0) -> -21359.147 | J48: =IF(J$19>ROUNDUP($B$14,0),IFERROR(IPMT($H$5,J$19-ROUNDUP($B$14,0),$H$6,$H$12*(1-$H$7)),-0.01),0) -> -20894.34 | K48: =IF(K$19>ROUNDUP($B$14,0),IFERROR(IPMT($H$5,K$19-ROUNDUP($B$14,0),$H$6,$H$12*(1-$H$7)),-0.01),0) -> -20424.885 | L48: =IF(L$19>ROUNDUP($B$14,0),IFERROR(IPMT($H$5,L$19-ROUNDUP($B$14,0),$H$6,$H$12*(1-$H$7)),-0.01),0) -> -19950.735 | ... AL48: =IF(AL$19>ROUNDUP($B$14,0),IFERROR(IPMT($H$5,AL$19-ROUNDUP($B$14,0),$H$6,$H$12*(1-$H$7)),-0.01),0) -> -5811.173
...

Sheet zitavska_HMBA
A1: Genericky investicny CF model
A2: Na jednom harku aby sa dal lahko kopirovat
A4: Predpoklady
A5: Nazov projektu | B5: Zitavska | D5: Pocet bytov (najomne byvanie) | E5: 34 | G5: Urokova sadzba SFRB | H5: 0.01 | J5: Urokova sadzba HMBA | K5: 0.04
A6: Stavebne naklady s DPH | B6: -5300000 | D6: Rozloha bytov (najomne byvanie) | E6: 1875 | G6: Maturita SFRB (roky) | H6: 40 | J6: Maturita HMBA (roky) | K6: 25
A7: Aplikovana sadzba DPH pre stavebne naklady | B7: 0.23 | D7: Jednotkove naklady bez DPH (eur/m2) | E7: =B8/E6 -> -2298.103 | G7: Podiel dotacie/SFRB | H7: 0.4 | J7: Urokova sadzba BOB | K7: 0.06
A8: Stavebne naklady bez DPH | B8: =B6/(1+$B$7) -> -4308943.1 | D8: Podiel bytov vhodnych na dotaciu/SFRB | E8: 1 | G8: Dotacny strop na m2 BOB | H8: 1980 | J8: Maturita BOB (roky, prevadzka) | K8: 25
A9: Investor | B9: HMBA | D9: NFA (m2) | E9: 2663 | G9: Dotacny strop na m2 HMBA | H9: 2140
M10: Relevantny HMBA uver | N10: =IF($B$9="BOB",N12,N11) -> 1688750
A11: DPH pre BOB | B11: 0.05 | D11: Najomne bytov/mesiac/m2 | E11: 7 | G11: SFRB+dotacia HMBA model | H11: =MIN(H9,-$E$7)*$E$6*0.9 -> 3611250 | J11: Frekvencia CAPEX obnovy | K11: 10 | M11: Potreba uveru HMBA (HMBA model) | N11: =-B8*(1+$B$12)-H11 -> 1688750
A12: DPH pre HMBA | B12: 0.23 | D12: Najomne nebytov/mesiac/m2 | E12: 2.5 | G12: SFRB+dotacia BOB model | H12: =MIN(H8,-$E$7)*$E$6 -> 3712500 | J12: Percento CAPEX obnovy | K12: 0.05 | M12: Potreba uveru HMBA (BOB model) | N12: =MAX(N13-H12,0) -> 0
A13: Indexacia najomneho p.a. | B13: 0.02 | D13: Fond oprav mesiac/m2 | E13: 1.5 | G13: Prijem z najomneho 1. rok (vratane fondu oprav, byty) | H13: =(E11+E13)*E6*12 -> 191250 | J13: Tvorba fondu na CAPEX opravy | K13: 0.007 | M13: Kupna cena od BOBu | N13: =MAX((-SUM(E44:AL44)+SUMIFS(E24:AL24,E18:AL18,">0"))*(1+B11)*(1+K14),0) -> 0
A14: Trvanie vystavby (roky) | B14: 1.5 | D14: Naklady na spravu a prevadkzu s DPH (/m2/rok) | E14: -11.3 | G14: Prijem z najomneho 1. rok (vratane fondu oprav, nebyty) | H14: =(E9-E6)*E12*12 -> 23640 | J14: Ziskova marza pre BOB | K14: 0.05 | M14: Overhead OPEX pre BOB / byt | N14: -1100
A16: Cashflow
A18: Fazovanie vystavby | E18: =IF(E$19<=ROUNDDOWN($B$14,0),(ROUNDDOWN($B$14,0)/$B$14)/ROUNDDOWN($B$14,0),IF(E$19=ROUNDUP($B$14,0),1-SUM($D$18:D18),0)) -> 0.66666667 | F18: =IF(F$19<=ROUNDDOWN($B$14,0),(ROUNDDOWN($B$14,0)/$B$14)/ROUNDDOWN($B$14,0),IF(F$19=ROUNDUP($B$14,0),1-SUM($D$18:E18),0)) -> 0.33333333 | G18: =IF(G$19<=ROUNDDOWN($B$14,0),(ROUNDDOWN($B$14,0)/$B$14)/ROUNDDOWN($B$14,0),IF(G$19=ROUNDUP($B$14,0),1-SUM($D$18:F18),0)) -> 0 | H18: =IF(H$19<=ROUNDDOWN($B$14,0),(ROUNDDOWN($B$14,0)/$B$14)/ROUNDDOWN($B$14,0),IF(H$19=ROUNDUP($B$14,0),1-SUM($D$18:G18),0)) -> 0 | I18: =IF(I$19<=ROUNDDOWN($B$14,0),(ROUNDDOWN($B$14,0)/$B$14)/ROUNDDOWN($B$14,0),IF(I$19=ROUNDUP($B$14,0),1-SUM($D$18:H18),0)) -> 0 | J18: =IF(J$19<=ROUNDDOWN($B$14,0),(ROUNDDOWN($B$14,0)/$B$14)/ROUNDDOWN($B$14,0),IF(J$19=ROUNDUP($B$14,0),1-SUM($D$18:I18),0)) -> 0 | K18: =IF(K$19<=ROUNDDOWN($B$14,0),(ROUNDDOWN($B$14,0)/$B$14)/ROUNDDOWN($B$14,0),IF(K$19=ROUNDUP($B$14,0),1-SUM($D$18:J18),0)) -> 0 | L18: =IF(L$19<=ROUNDDOWN($B$14,0),(ROUNDDOWN($B$14,0)/$B$14)/ROUNDDOWN($B$14,0),IF(L$19=ROUNDUP($B$14,0),1-SUM($D$18:K18),0)) -> 0 | M18: =IF(M$19<=ROUNDDOWN($B$14,0),(ROUNDDOWN($B$14,0)/$B$14)/ROUNDDOWN($B$14,0),IF(M$19=ROUNDUP($B$14,0),1-SUM($D$18:L18),0)) -> 0
A19: Polozka | B19: Vlastnik polozky | C19: DPH | D19: PV | E19: 1 | F19: 2 | G19: 3 | H19: 4 | I19: 5 | J19: 6 | K19: 7 | L19: 8 | M19: 9 | N19: 10 | O19: 11 | P19: 12 | Q19: 13 | R19: 14 | S19: 15 | T19: 16 | U19: 17 | V19: 18 | W19: 19 | X19: 20 | Y19: 21 | Z19: 22 | AA19: 23 | AB19: 24 | AC19: 25 | AD19: 26 | AE19: 27 | AF19: 28 | AG19: 29 | AH19: 30 | AI19: 31 | AJ19: 32 | AK19: 33 | AL19: 34
A20: Naklady bez DPH
A21: CAPEX vystavba | B21: =$B$9 -> HMBA | C21: =B21="BOB" -> FALSE | D21: =E21+NPV($K$5,F21:AK21) -> -5232051.3 | E21: =IF($B21="BOB",$B$8,$B$6)*E$18 -> -3533333.3 | F21: =IF($B21="BOB",$B$8,$B$6)*F$18 -> -1766666.7 | G21: =IF($B21="BOB",$B$8,$B$6)*G$18 -> 0 | H21: =IF($B21="BOB",$B$8,$B$6)*H$18 -> 0 | I21: =IF($B21="BOB",$B$8,$B$6)*I$18 -> 0 | J21: =IF($B21="BOB",$B$8,$B$6)*J$18 -> 0 | K21: =IF($B21="BOB",$B$8,$B$6)*K$18 -> 0 | L21: =IF($B21="BOB",$B$8,$B$6)*L$18 -> 0 | ... AL21: =IF($B21="BOB",$B$8,$B$6)*AL$18 -> 0
A22: CAPEX obnova | B22: HMBA | C22: =B22="BOB" -> FALSE | D22: =E22+NPV($K$5,F22:AK22) -> -366991.82 | E22: =IF(E$19<($K$11+ROUNDUP($B$14,0)),0,IF(MOD(E$19-ROUNDUP($B$14,0),$K$11)=0,$B$6*$K$12*POWER(1+$B$13,E$19-ROUNDUP(E19,0)),0)) -> 0 | F22: =IF(F$19<($K$11+ROUNDUP($B$14,0)),0,IF(MOD(F$19-ROUNDUP($B$14,0),$K$11)=0,$B$6*$K$12*POWER(1+$B$13,F$19-ROUNDUP(F19,0)),0)) -> 0 | G22: =IF(G$19<($K$11+ROUNDUP($B$14,0)),0,IF(MOD(G$19-ROUNDUP($B$14,0),$K$11)=0,$B$6*$K$12*POWER(1+$B$13,G$19-ROUNDUP(G19,0)),0)) -> 0 | H22: =IF(H$19<($K$11+ROUNDUP($B$14,0)),0,IF(MOD(H$19-ROUNDUP($B$14,0),$K$11)=0,$B$6*$K$12*POWER(1+$B$13,H$19-ROUNDUP(H19,0)),0)) -> 0 | I22: =IF(I$19<($K$11+ROUNDUP($B$14,0)),0,IF(MOD(I$19-ROUNDUP($B$14,0),$K$11)=0,$B$6*$K$12*POWER(1+$B$13,I$19-ROUNDUP(I19,0)),0)) -> 0 | J22: =IF(J$19<($K$11+ROUNDUP($B$14,0)),0,IF(MOD(J$19-ROUNDUP($B$14,0),$K$11)=0,$B$6*$K$12*POWER(1+$B$13,J$19-ROUNDUP(J19,0)),0)) -> 0 | K22: =IF(K$19<($K$11+ROUNDUP($B$14,0)),0,IF(MOD(K$19-ROUNDUP($B$14,0),$K$11)=0,$B$6*$K$12*POWER(1+$B$13,K$19-ROUNDUP(K19,0)),0)) -> 0 | L22: =IF(L$19<($K$11+ROUNDUP($B$14,0)),0,IF(MOD(L$19-ROUNDUP($B$14,0),$K$11)=0,$B$6*$K$12*POWER(1+$B$13,L$19-ROUNDUP(L19,0)),0)) -> 0 | ... AL22: =IF(AL$19<($K$11+ROUNDUP($B$14,0)),0,IF(MOD(AL$19-ROUNDUP($B$14,0),$K$11)=0,$B$6*$K$12*POWER(1+$B$13,AL$19-ROUNDUP(AL19,0)),0)) -> 0
A24: DPH na vstupe | B24: BOB | D24: =E24+NPV($K$5,F24:AK24) -> 0 | E24: =SUMIFS(E$21:E$23,$C$21:$C$23,TRUE)*$B$12 -> 0 | F24: =SUMIFS(F$21:F$23,$C$21:$C$23,TRUE)*$B$12 -> 0 | G24: =SUMIFS(G$21:G$23,$C$21:$C$23,TRUE)*$B$12 -> 0 | H24: =SUMIFS(H$21:H$23,$C$21:$C$23,TRUE)*$B$12 -> 0 | I24: =SUMIFS(I$21:I$23,$C$21:$C$23,TRUE)*$B$12 -> 0 | J24: =SUMIFS(J$21:J$23,$C$21:$C$23,TRUE)*$B$12 -> 0 | K24: =SUMIFS(K$21:K$23,$C$21:$C$23,TRUE)*$B$12 -> 0 | L24: =SUMIFS(L$21:L$23,$C$21:$C$23,TRUE)*$B$12 -> 0 | ... AL24: =SUMIFS(AL$21:AL$23,$C$21:$C$23,TRUE)*$B$12 -> 0
A26: Najomne a fond oprav
A27: Prijem z najomneho byty | B27: HMBA | C27: FALSE | D27: =E27+NPV($K$5,F27:AK27) -> 4376667.6 | E27: =IF(E19>$B$14,$H$13*POWER(1+$B$13,E$19-$B$14),0)*(1-(($B$14-ROUNDDOWN($B$14,0))*IF(E$19=ROUNDUP($B$14,0),1,0))) -> 0 | F27: =IF(F19>$B$14,$H$13*POWER(1+$B$13,F$19-$B$14),0)*(1-(($B$14-ROUNDDOWN($B$14,0))*IF(F$19=ROUNDUP($B$14,0),1,0))) -> 96576.516 | G27: =IF(G19>$B$14,$H$13*POWER(1+$B$13,G$19-$B$14),0)*(1-(($B$14-ROUNDDOWN($B$14,0))*IF(G$19=ROUNDUP($B$14,0),1,0))) -> 197016.09 | H27: =IF(H19>$B$14,$H$13*POWER(1+$B$13,H$19-$B$14),0)*(1-(($B$14-ROUNDDOWN($B$14,0))*IF(H$19=ROUNDUP($B$14,0),1,0))) -> 200956.41 | I27: =IF(I19>$B$14,$H$13*POWER(1+$B$13,I$19-$B$14),0)*(1-(($B$14-ROUNDDOWN($B$14,0))*IF(I$19=ROUNDUP($B$14,0),1,0))) -> 204975.54 | J27: =IF(J19>$B$14,$H$13*POWER(1+$B$13,J$19-$B$14),0)*(1-(($B$14-ROUNDDOWN($B$14,0))*IF(J$19=ROUNDUP($B$14,0),1,0))) -> 209075.05 | K27: =IF(K19>$B$14,$H$13*POWER(1+$B$13,K$19-$B$14),0)*(1-(($B$14-ROUNDDOWN($B$14,0))*IF(K$19=ROUNDUP($B$14,0),1,0))) -> 213256.55 | L27: =IF(L19>$B$14,$H$13*POWER(1+$B$13,L$19-$B$14),0)*(1-(($B$14-ROUNDDOWN($B$14,0))*IF(L$19=ROUNDUP($B$14,0),1,0))) -> 217521.69 | ... AL27: =IF(AL19>$B$14,$H$13*POWER(1+$B$13,AL$19-$B$14),0)*(1-(($B$14-ROUNDDOWN($B$14,0))*IF(AL$19=ROUNDUP($B$14,0),1,0))) -> 364004.73
A28: Prijem z najomneho nebyty | B28: HMBA | C28: FALSE | D28: =E28+NPV($K$5,F28:AK28) -> 540990.45 | E28: =IF(E19>$B$14,$H$14*POWER(1+$B$13,E$19-$B$14),0)*(1-(($B$14-ROUNDDOWN($B$14,0))*IF(E$19=ROUNDUP($B$14,0),1,0))) -> 0 | F28: =IF(F19>$B$14,$H$14*POWER(1+$B$13,F$19-$B$14),0)*(1-(($B$14-ROUNDDOWN($B$14,0))*IF(F$19=ROUNDUP($B$14,0),1,0))) -> 11937.615 | G28: =IF(G19>$B$14,$H$14*POWER(1+$B$13,G$19-$B$14),0)*(1-(($B$14-ROUNDDOWN($B$14,0))*IF(G$19=ROUNDUP($B$14,0),1,0))) -> 24352.734 | H28: =IF(H19>$B$14,$H$14*POWER(1+$B$13,H$19-$B$14),0)*(1-(($B$14-ROUNDDOWN($B$14,0))*IF(H$19=ROUNDUP($B$14,0),1,0))) -> 24839.789 | I28: =IF(I19>$B$14,$H$14*POWER(1+$B$13,I$19-$B$14),0)*(1-(($B$14-ROUNDDOWN($B$14,0))*IF(I$19=ROUNDUP($B$14,0),1,0))) -> 25336.585 | J28: =IF(J19>$B$14,$H$14*POWER(1+$B$13,J$19-$B$14),0)*(1-(($B$14-ROUNDDOWN($B$14,0))*IF(J$19=ROUNDUP($B$14,0),1,0))) -> 25843.316 | K28: =IF(K19>$B$14,$H$14*POWER(1+$B$13,K$19-$B$14),0)*(1-(($B$14-ROUNDDOWN($B$14,0))*IF(K$19=ROUNDUP($B$14,0),1,0))) -> 26360.183 | L28: =IF(L19>$B$14,$H$14*POWER(1+$B$13,L$19-$B$14),0)*(1-(($B$14-ROUNDDOWN($B$14,0))*IF(L$19=ROUNDUP($B$14,0),1,0))) -> 26887.386 | ... AL28: =IF(AL19>$B$14,$H$14*POWER(1+$B$13,AL$19-$B$14),0)*(1-(($B$14-ROUNDDOWN($B$14,0))*IF(AL$19=ROUNDUP($B$14,0),1,0))) -> 44993.839
A29: Tvorba fondu oprav na CAPEX | C29: FALSE | D29: =E29+NPV($K$5,F29:AK29) -> -867030.33 | E29: =IF(E27>0,$B$6*$K$13*POWER(1+$B$13,E$19-$B$14),0) -> 0 | F29: =IF(F27>0,$B$6*$K$13*POWER(1+$B$13,F$19-$B$14),0) -> -37469.163 | G29: =IF(G27>0,$B$6*$K$13*POWER(1+$B$13,G$19-$B$14),0) -> -38218.547 | H29: =IF(H27>0,$B$6*$K$13*POWER(1+$B$13,H$19-$B$14),0) -> -38982.918 | I29: =IF(I27>0,$B$6*$K$13*POWER(1+$B$13,I$19-$B$14),0) -> -39762.576 | J29: =IF(J27>0,$B$6*$K$13*POWER(1+$B$13,J$19-$B$14),0) -> -40557.827 | K29: =IF(K27>0,$B$6*$K$13*POWER(1+$B$13,K$19-$B$14),0) -> -41368.984 | L29: =IF(L27>0,$B$6*$K$13*POWER(1+$B$13,L$19-$B$14),0) -> -42196.364 | ... AL29: =IF(AL27>0,$B$6*$K$13*POWER(1+$B$13,AL$19-$B$14),0) -> -70612.159
A30: Cerpanie fondu oprav na CAPEX | C30: FALSE | D30: =E30+NPV($K$5,F30:AK30) -> 366991.82 | E30: =-E22 -> 0 | F30: =-F22 -> 0 | G30: =-G22 -> 0 | H30: =-H22 -> 0 | I30: =-I22 -> 0 | J30: =-J22 -> 0 | K30: =-K22 -> 0 | L30: =-L22 -> 0 | ... AL30: =-AL22 -> 0
A31: Zostatok fondu oprav na CAPEX | E31: 0 | F31: =E31-F29-F30 -> 37469.163 | G31: =F31-G29-G30 -> 75687.71 | H31: =G31-H29-H30 -> 114670.63 | I31: =H31-I29-I30 -> 154433.2 | J31: =I31-J29-J30 -> 194991.03 | K31: =J31-K29-K30 -> 236360.01 | L31: =K31-L29-L30 -> 278556.38 | M31: =L31-M29-M30 -> 321596.67 | ... AL31: =AK31-AL29-AL30 -> 932761.95
A33: Financovanie
A34: Cerpanie komercneho uveru (bullet) | B34: BOB | C34: FALSE | D34: =E34+NPV($K$5,F34:AK34) -> 0 | E34: =IF($B$21="BOB",IF(E18>0,-E21-E24,0),0) -> 0 | F34: =IF($B$21="BOB",IF(F18>0,-F21-F24,0),0) -> 0 | G34: =IF($B$21="BOB",IF(G18>0,-G21-G24,0),0) -> 0 | H34: =IF($B$21="BOB",IF(H18>0,-H21-H24,0),0) -> 0 | I34: =IF($B$21="BOB",IF(I18>0,-I21-I24,0),0) -> 0 | J34: =IF($B$21="BOB",IF(J18>0,-J21-J24,0),0) -> 0 | K34: =IF($B$21="BOB",IF(K18>0,-K21-K24,0),0) -> 0 | L34: =IF($B$21="BOB",IF(L18>0,-L21-L24,0),0) -> 0 | ... AL34: =IF($B$21="BOB",IF(AL18>0,-AL21-AL24,0),0) -> 0
A35: Dotacia SFRB | B35: HMBA | C35: FALSE | D35: =E35+NPV($K$5,F35:AK35) -> 1388942.3 | E35: =IF(E$19=ROUNDUP($B$14,0),IF($B$21="BOB",$H$12,$H$11)*$H$7,0) -> 0 | F35: =IF(F$19=ROUNDUP($B$14,0),IF($B$21="BOB",$H$12,$H$11)*$H$7,0) -> 1444500 | G35: =IF(G$19=ROUNDUP($B$14,0),IF($B$21="BOB",$H$12,$H$11)*$H$7,0) -> 0 | H35: =IF(H$19=ROUNDUP($B$14,0),IF($B$21="BOB",$H$12,$H$11)*$H$7,0) -> 0 | I35: =IF(I$19=ROUNDUP($B$14,0),IF($B$21="BOB",$H$12,$H$11)*$H$7,0) -> 0 | J35: =IF(J$19=ROUNDUP($B$14,0),IF($B$21="BOB",$H$12,$H$11)*$H$7,0) -> 0 | K35: =IF(K$19=ROUNDUP($B$14,0),IF($B$21="BOB",$H$12,$H$11)*$H$7,0) -> 0 | L35: =IF(L$19=ROUNDUP($B$14,0),IF($B$21="BOB",$H$12,$H$11)*$H$7,0) -> 0 | ... AL35: =IF(AL$19=ROUNDUP($B$14,0),IF($B$21="BOB",$H$12,$H$11)*$H$7,0) -> 0
A36: Uver SFRB | B36: HMBA | C36: FALSE | D36: =E36+NPV($K$5,F36:AK36) -> 2083413.5 | E36: =IF(E$19=ROUNDUP($B$14,0),IF($B$21="BOB",$H$12,$H$11)*(1-$H$7),0) -> 0 | F36: =IF(F$19=ROUNDUP($B$14,0),IF($B$21="BOB",$H$12,$H$11)*(1-$H$7),0) -> 2166750 | G36: =IF(G$19=ROUNDUP($B$14,0),IF($B$21="BOB",$H$12,$H$11)*(1-$H$7),0) -> 0 | H36: =IF(H$19=ROUNDUP($B$14,0),IF($B$21="BOB",$H$12,$H$11)*(1-$H$7),0) -> 0 | I36: =IF(I$19=ROUNDUP($B$14,0),IF($B$21="BOB",$H$12,$H$11)*(1-$H$7),0) -> 0 | J36: =IF(J$19=ROUNDUP($B$14,0),IF($B$21="BOB",$H$12,$H$11)*(1-$H$7),0) -> 0 | K36: =IF(K$19=ROUNDUP($B$14,0),IF($B$21="BOB",$H$12,$H$11)*(1-$H$7),0) -> 0 | L36: =IF(L$19=ROUNDUP($B$14,0),IF($B$21="BOB",$H$12,$H$11)*(1-$H$7),0) -> 0 | ... AL36: =IF(AL$19=ROUNDUP($B$14,0),IF($B$21="BOB",$H$12,$H$11)*(1-$H$7),0) -> 0
A37: Uver HMBA | B37: HMBA | C37: FALSE | D37: =E37+NPV($K$5,F37:AK37) -> 1623798.1 | E37: =IF(E$19=ROUNDUP($B$14,0),$N$10,0) -> 0 | F37: =IF(F$19=ROUNDUP($B$14,0),$N$10,0) -> 1688750 | G37: =IF(G$19=ROUNDUP($B$14,0),$N$10,0) -> 0 | H37: =IF(H$19=ROUNDUP($B$14,0),$N$10,0) -> 0 | I37: =IF(I$19=ROUNDUP($B$14,0),$N$10,0) -> 0 | J37: =IF(J$19=ROUNDUP($B$14,0),$N$10,0) -> 0 | K37: =IF(K$19=ROUNDUP($B$14,0),$N$10,0) -> 0 | L37: =IF(L$19=ROUNDUP($B$14,0),$N$10,0) -> 0 | ... AL37: =IF(AL$19=ROUNDUP($B$14,0),$N$10,0) -> 0
A38: Kupa bytov do vlastnictva HMBA | B38: HMBA | C38: FALSE | D38: =E38+NPV($K$5,F38:AK38) -> 0 | E38: =IF($B$21="BOB",IF(E$19=ROUNDUP($B$14,0),-$H$12-$N$12,0),0) -> 0 | F38: =IF($B$21="BOB",IF(F$19=ROUNDUP($B$14,0),-$H$12-$N$12,0),0) -> 0 | G38: =IF($B$21="BOB",IF(G$19=ROUNDUP($B$14,0),-$H$12-$N$12,0),0) -> 0 | H38: =IF($B$21="BOB",IF(H$19=ROUNDUP($B$14,0),-$H$12-$N$12,0),0) -> 0 | I38: =IF($B$21="BOB",IF(I$19=ROUNDUP($B$14,0),-$H$12-$N$12,0),0) -> 0 | J38: =IF($B$21="BOB",IF(J$19=ROUNDUP($B$14,0),-$H$12-$N$12,0),0) -> 0 | K38: =IF($B$21="BOB",IF(K$19=ROUNDUP($B$14,0),-$H$12-$N$12,0),0) -> 0 | L38: =IF($B$21="BOB",IF(L$19=ROUNDUP($B$14,0),-$H$12-$N$12,0),0) -> 0 | ... AL38: =IF($B$21="BOB",IF(AL$19=ROUNDUP($B$14,0),-$H$12-$N$12,0),0) -> 0
A39: Prijem z predaja bytov | B39: BOB | C39: TRUE | D39: =E39+NPV($K$5,F39:AK39) -> 0 | E39: =-E38/(1+$B$11) -> 0 | F39: =-F38/(1+$B$11) -> 0 | G39: =-G38/(1+$B$11) -> 0 | H39: =-H38/(1+$B$11) -> 0 | I39: =-I38/(1+$B$11) -> 0 | J39: =-J38/(1+$B$11) -> 0 | K39: =-K38/(1+$B$11) -> 0 | L39: =-L38/(1+$B$11) -> 0 | ... AL39: =-AL38/(1+$B$11) -> 0
A40: DPH na vystupe | B40: BOB | D40: =E40+NPV($K$5,F40:AK40) -> 0 | E40: =SUMIFS(E$34:E$39,$C$34:$C$39,TRUE)*$B$11 -> 0 | F40: =SUMIFS(F$34:F$39,$C$34:$C$39,TRUE)*$B$11 -> 0 | G40: =SUMIFS(G$34:G$39,$C$34:$C$39,TRUE)*$B$11 -> 0 | H40: =SUMIFS(H$34:H$39,$C$34:$C$39,TRUE)*$B$11 -> 0 | I40: =SUMIFS(I$34:I$39,$C$34:$C$39,TRUE)*$B$11 -> 0 | J40: =SUMIFS(J$34:J$39,$C$34:$C$39,TRUE)*$B$11 -> 0 | K40: =SUMIFS(K$34:K$39,$C$34:$C$39,TRUE)*$B$11 -> 0 | L40: =SUMIFS(L$34:L$39,$C$34:$C$39,TRUE)*$B$11 -> 0 | ... AL40: =SUMIFS(AL$34:AL$39,$C$34:$C$39,TRUE)*$B$11 -> 0
A42: Dlhova sluzba
A43: Kapitalizacia urokov komercneho uveru | B43: FALSE | C43: FALSE | E43: =E34*0.5*$K$7*IF(E18=0,0,1) -> 0 | F43: =(SUM($E$34:E34)+F34*0.5)*$K$7*IF(F18=0,0,1) -> 0 | G43: =(SUM($E$34:F34)+G34*0.5)*$K$7*IF(G18=0,0,1) -> 0 | H43: =(SUM($E$34:G34)+H34*0.5)*$K$7*IF(H18=0,0,1) -> 0 | I43: =(SUM($E$34:H34)+I34*0.5)*$K$7*IF(I18=0,0,1) -> 0 | J43: =(SUM($E$34:I34)+J34*0.5)*$K$7*IF(J18=0,0,1) -> 0 | K43: =(SUM($E$34:J34)+K34*0.5)*$K$7*IF(K18=0,0,1) -> 0 | L43: =(SUM($E$34:K34)+L34*0.5)*$K$7*IF(L18=0,0,1) -> 0 | M43: =(SUM($E$34:L34)+M34*0.5)*$K$7*IF(M18=0,0,1) -> 0 | ... AL43: =(SUM($E$34:AK34)+AL34*0.5)*$K$7*IF(AL18=0,0,1) -> 0
A44: Splatka komercneho uveru | B44: BOB | C44: FALSE | D44: =E44+NPV($K$5,F44:AK44) -> 0 | E44: =-IF(E19=ROUNDUP($B$14,0),SUM($E$34:$AL$34,$E$43:$AL$43),0) -> 0 | F44: =-IF(F19=ROUNDUP($B$14,0),SUM($E$34:$AL$34,$E$43:$AL$43),0) -> 0 | G44: =-IF(G19=ROUNDUP($B$14,0),SUM($E$34:$AL$34,$E$43:$AL$43),0) -> 0 | H44: =-IF(H19=ROUNDUP($B$14,0),SUM($E$34:$AL$34,$E$43:$AL$43),0) -> 0 | I44: =-IF(I19=ROUNDUP($B$14,0),SUM($E$34:$AL$34,$E$43:$AL$43),0) -> 0 | J44: =-IF(J19=ROUNDUP($B$14,0),SUM($E$34:$AL$34,$E$43:$AL$43),0) -> 0 | K44: =-IF(K19=ROUNDUP($B$14,0),SUM($E$34:$AL$34,$E$43:$AL$43),0) -> 0 | L44: =-IF(L19=ROUNDUP($B$14,0),SUM($E$34:$AL$34,$E$43:$AL$43),0) -> 0 | ... AL44: =-IF(AL19=ROUNDUP($B$14,0),SUM($E$34:$AL$34,$E$43:$AL$43),0) -> 0
A45: Splatka uveru HMBA (istina) | B45: HMBA | C45: FALSE | D45: =E45+NPV($K$5,F45:AK45) -> -937273.51 | E45: =IF(E$19>ROUNDUP($B$14,0),IF(E46<>-0.01,PPMT($K$5,E$19-ROUNDUP($B$14,0),$K$6,$N$10),0.01),0) -> 0 | F45: =IF(F$19>ROUNDUP($B$14,0),IF(F46<>-0.01,PPMT($K$5,F$19-ROUNDUP($B$14,0),$K$6,$N$10),0.01),0) -> 0 | G45: =IF(G$19>ROUNDUP($B$14,0),IF(G46<>-0.01,PPMT($K$5,G$19-ROUNDUP($B$14,0),$K$6,$N$10),0.01),0) -> -40550.202 | H45: =IF(H$19>ROUNDUP($B$14,0),IF(H46<>-0.01,PPMT($K$5,H$19-ROUNDUP($B$14,0),$K$6,$N$10),0.01),0) -> -42172.21 | I45: =IF(I$19>ROUNDUP($B$14,0),IF(I46<>-0.01,PPMT($K$5,I$19-ROUNDUP($B$14,0),$K$6,$N$10),0.01),0) -> -43859.099 | J45: =IF(J$19>ROUNDUP($B$14,0),IF(J46<>-0.01,PPMT($K$5,J$19-ROUNDUP($B$14,0),$K$6,$N$10),0.01),0) -> -45613.463 | K45: =IF(K$19>ROUNDUP($B$14,0),IF(K46<>-0.01,PPMT($K$5,K$19-ROUNDUP($B$14,0),$K$6,$N$10),0.01),0) -> -47438.001 | L45: =IF(L$19>ROUNDUP($B$14,0),IF(L46<>-0.01,PPMT($K$5,L$19-ROUNDUP($B$14,0),$K$6,$N$10),0.01),0) -> -49335.521 | ... AL45: =IF(AL$19>ROUNDUP($B$14,0),IF(AL46<>-0.01,PPMT($K$5,AL$19-ROUNDUP($B$14,0),$K$6,$N$10),0.01),0) -> 0.01
A46: Splatka uveru HMBA (uroky) | B46: HMBA | C46: FALSE | D46: =E46+NPV($K$5,F46:AK46) -> -686524.56 | E46: =IF(E$19>ROUNDUP($B$14,0),IFERROR(IPMT($K$5,E$19-ROUNDUP($B$14,0),$K$6,$N$10),-0.01),0) -> 0 | F46: =IF(F$19>ROUNDUP($B$14,0),IFERROR(IPMT($K$5,F$19-ROUNDUP($B$14,0),$K$6,$N$10),-0.01),0) -> 0 | G46: =IF(G$19>ROUNDUP($B$14,0),IFERROR(IPMT($K$5,G$19-ROUNDUP($B$14,0),$K$6,$N$10),-0.01),0) -> -67550 | H46: =IF(H$19>ROUNDUP($B$14,0),IFERROR(IPMT($K$5,H$19-ROUNDUP($B$14,0),$K$6,$N$10),-0.01),0) -> -65927.992 | I46: =IF(I$19>ROUNDUP($B$14,0),IFERROR(IPMT($K$5,I$19-ROUNDUP($B$14,0),$K$6,$N$10),-0.01),0) -> -64241.104 | J46: =IF(J$19>ROUNDUP($B$14,0),IFERROR(IPMT($K$5,J$19-ROUNDUP($B$14,0),$K$6,$N$10),-0.01),0) -> -62486.74 | K46: =IF(K$19>ROUNDUP($B$14,0),IFERROR(IPMT($K$5,K$19-ROUNDUP($B$14,0),$K$6,$N$10),-0.01),0) -> -60662.201 | L46: =IF(L$19>ROUNDUP($B$14,0),IFERROR(IPMT($K$5,L$19-ROUNDUP($B$14,0),$K$6,$N$10),-0.01),0) -> -58764.681 | ... AL46: =IF(AL$19>ROUNDUP($B$14,0),IFERROR(IPMT($K$5,AL$19-ROUNDUP($B$14,0),$K$6,$N$10),-0.01),0) -> -0.01
A47: Splatka uveru SFRB (istina) | B47: HMBA | C47: FALSE | D47: =E47+NPV($K$5,F47:AK47) -> -847264.43 | E47: =IF(E$19>ROUNDUP($B$14,0),IF(E48<>-0.01,PPMT($H$5,E$19-ROUNDUP($B$14,0),$H$6,IF($B$9="BOB",$H$12,$H$11)*(1-$H$7)),0.01),0) -> 0 | F47: =IF(F$19>ROUNDUP($B$14,0),IF(F48<>-0.01,PPMT($H$5,F$19-ROUNDUP($B$14,0),$H$6,IF($B$9="BOB",$H$12,$H$11)*(1-$H$7)),0.01),0) -> 0 | G47: =IF(G$19>ROUNDUP($B$14,0),IF(G48<>-0.01,PPMT($H$5,G$19-ROUNDUP($B$14,0),$H$6,IF($B$9="BOB",$H$12,$H$11)*(1-$H$7)),0.01),0) -> -44322.167 | H47: =IF(H$19>ROUNDUP($B$14,0),IF(H48<>-0.01,PPMT($H$5,H$19-ROUNDUP($B$14,0),$H$6,IF($B$9="BOB",$H$12,$H$11)*(1-$H$7)),0.01),0) -> -44765.389 | I47: =IF(I$19>ROUNDUP($B$14,0),IF(I48<>-0.01,PPMT($H$5,I$19-ROUNDUP($B$14,0),$H$6,IF($B$9="BOB",$H$12,$H$11)*(1-$H$7)),0.01),0) -> -45213.042 | J47: =IF(J$19>ROUNDUP($B$14,0),IF(J48<>-0.01,PPMT($H$5,J$19-ROUNDUP($B$14,0),$H$6,IF($B$9="BOB",$H$12,$H$11)*(1-$H$7)),0.01),0) -> -45665.173 | K47: =IF(K$19>ROUNDUP($B$14,0),IF(K48<>-0.01,PPMT($H$5,K$19-ROUNDUP($B$14,0),$H$6,IF($B$9="BOB",$H$12,$H$11)*(1-$H$7)),0.01),0) -> -46121.825 | L47: =IF(L$19>ROUNDUP($B$14,0),IF(L48<>-0.01,PPMT($H$5,L$19-ROUNDUP($B$14,0),$H$6,IF($B$9="BOB",$H$12,$H$11)*(1-$H$7)),0.01),0) -> -46583.043 | ... AL47: =IF(AL$19>ROUNDUP($B$14,0),IF(AL48<>-0.01,PPMT($H$5,AL$19-ROUNDUP($B$14,0),$H$6,IF($B$9="BOB",$H$12,$H$11)*(1-$H$7)),0.01),0) -> -60336.98
...

Sheet antolska_porovnanie
A1: Vystavba BD Antolska
A2: Porovnanie investicie cez BOB a priamo cez HMBA
A4: Vysledok za konsolidovany celok HMBA
A5: Sucasne hodnoty financnych tokov | B5: Model BOB | C5: Model HMBA
A6: Vydavky | B6: =B7+B8 -> -17356250 | C6: =C7+C8 -> -21216751
A7: CAPEX (vystavba + udrzba) | B7: =antolska_BOB!D21+antolska_BOB!D22 -> -14065632 | C7: =antolska_HMBA!D21+antolska_HMBA!D22 -> -17383043
A8: OPEX (udrba + overhead) | B8: =antolska_BOB!D62+antolska_BOB!D63 -> -3290618 | C8: =antolska_HMBA!D62+antolska_HMBA!D63 -> -3833708.1
A9: Prijmy | B9: =B10+B11+B12 -> 10047085 | C9: =C10+C11+C12 -> 11650930
A10: Cisty prijem z najomneho | B10: =SUM(antolska_BOB!D27:D28) -> 10942427 | C10: =SUM(antolska_HMBA!D27:D28) -> 11650930
A11: Cisty financny tok z kupy bytov (HMBA od BOB) | B11: =antolska_BOB!D38+antolska_BOB!D39 -> -730811.6 | C11: 0
A12: Cisty financny tok z poplatku za spravu (HMBA pre BOB) | B12: =antolska_BOB!D61+antolska_BOB!D60 -> -164530.9 | C12: 0
A13: Financovanie | B13: =B14+B15+B16+B17 -> 4446105.9 | C13: =SUM(C14:C17) -> 5276939.6
A14: Dotacia a uver SFRB | B14: =antolska_BOB!D35+antolska_BOB!D36 -> 7686778.8 | C14: =antolska_HMBA!D36+antolska_HMBA!D35 -> 7776225
A15: Uvery (bullet aj dlhodoby uver HMBA) | B15: =antolska_BOB!D34+antolska_BOB!D37 -> 23613457 | C15: =antolska_HMBA!D34+antolska_HMBA!D37 -> 8045525
A16: Splatky komercnych uverov/uveru HMBA | B16: =antolska_BOB!D44+antolska_BOB!D46+antolska_BOB!D45 -> -24425235 | C16: =antolska_HMBA!D44+antolska_HMBA!D45+antolska_HMBA!D46 -> -8045525
A17: Splatka SFRB uveru | B17: =antolska_BOB!D47+antolska_BOB!D48 -> -2428895.5 | C17: =antolska_HMBA!D47+antolska_HMBA!D48 -> -2499285.4
A18: DPH | B18: =SUM(B19:B20) -> -80624.213 | C18: =SUM(C19:C20) -> 0
A19: DPH na vstupe/vystupe | B19: =antolska_BOB!D24+antolska_BOB!D40+antolska_BOB!D64+antolska_BOB!D65 -> -2155157.2 | C19: 0
A20: Vratky DPH | B20: =antolska_BOB!D51+antolska_BOB!D66 -> 2074533 | C20: 0
A22: Cisty financny tok (BOB+HMBA) | B22: =B6+B9+B13+B18 -> -2943683.7 | C22: =C6+C9+C13+C18 -> -4288881.6
A23: Relativna vyhodnost BOB oproti HMBA | C23: =B22-C22 -> 1345197.9
A24: ROI | B24: =-B22/B7 -> -0.20928201 | C24: =-C22/C7 -> -0.2467279

Sheet antolska_BOB
A1: Genericky investicny CF model
A2: Na jednom harku aby sa dal lahko kopirovat
A4: Predpoklady
A5: Nazov projektu | B5: Antolska | D5: Pocet bytov (najomne byvanie) | E5: 83 | G5: Urokova sadzba SFRB | H5: 0.01 | J5: Urokova sadzba HMBA | K5: 0.04
A6: Stavebne naklady s DPH | B6: -16454620 | D6: Rozloha bytov (najomne byvanie) | E6: 4199 | G6: Maturita SFRB (roky) | H6: 40 | J6: Maturita HMBA (roky) | K6: 25
A7: Aplikovana sadzba DPH pre stavebne naklady | B7: 0.23 | D7: Jednotkove naklady bez DPH (eur/m2) | E7: =B8/E6 -> -3185.9347 | G7: Podiel dotacie/SFRB | H7: 0.4 | J7: Urokova sadzba BOB | K7: 0.06
A8: Stavebne naklady bez DPH | B8: =B6/(1+$B$7) -> -13377740 | D8: Podiel bytov vhodnych na dotaciu/SFRB | E8: 1 | G8: Dotacny strop na m2 BOB | H8: 1980 | J8: Maturita BOB (roky, prevadzka) | K8: 25
A9: NFA (m2) | B9: 6893 | G9: Dotacny strop na m2 HMBA | H9: 2140
A11: DPH pre BOB | B11: 0.05 | D11: Najomne bytov/mesiac/m2 | E11: 7 | G11: SFRB+dotacia HMBA model | H11: =MIN(H9,-$E$7)*$E$6*0.9 -> 8087274 | J11: Frekvencia CAPEX obnovy | K11: 10 | M11: Potreba uveru HMBA (HMBA model) | N11: =-B8*(1+$B$12)-H11 -> 8367346
A12: DPH pre HMBA | B12: 0.23 | D12: Najomne nebytov/mesiac/m2 | E12: 2.5 | G12: SFRB+dotacia BOB model | H12: =MIN(H8,-$E$7)*$E$6 -> 8314020 | J12: Percento CAPEX obnovy | K12: 0.05 | M12: Potreba uveru HMBA (BOB model) | N12: =N13-H12 -> 8285342.5
A13: Indexacia najomneho p.a. | B13: 0.02 | D13: Fond oprav mesiac/m2 | E13: 1.5 | G13: Prijem z najomneho 1. rok (vratane fondu oprav, byty) | H13: =(E11+E13)*E6*12 -> 428298 | J13: Tvorba fondu na CAPEX opravy | K13: 0.007 | M13: Kupna cena od BOBu | N13: =(-SUM(E44:AL44)+SUMIFS(E24:AL24,E18:AL18,">0"))*(1+B11)*(1+K14) -> 16599362
A14: Trvanie vystavby (roky) | B14: 2.5 | D14: Naklady na spravu a prevadkzu s DPH (/m2/rok) | E14: -11.3 | G14: Prijem z najomneho 1. rok (vratane fondu oprav, nebyty) | H14: =(B9-E6)*E12*12 -> 80820 | J14: Ziskova marza pre BOB | K14: 0.05 | M14: Overhead OPEX pre BOB / byt | N14: -1100
A16: Cashflow
A18: Fazovanie vystavby | E18: =IF(E$19<=ROUNDDOWN($B$14,0),(ROUNDDOWN($B$14,0)/$B$14)/ROUNDDOWN($B$14,0),IF(E$19=ROUNDUP($B$14,0),1-SUM($D$18:D18),0)) -> 0.4 | F18: =IF(F$19<=ROUNDDOWN($B$14,0),(ROUNDDOWN($B$14,0)/$B$14)/ROUNDDOWN($B$14,0),IF(F$19=ROUNDUP($B$14,0),1-SUM($D$18:E18),0)) -> 0.4 | G18: =IF(G$19<=ROUNDDOWN($B$14,0),(ROUNDDOWN($B$14,0)/$B$14)/ROUNDDOWN($B$14,0),IF(G$19=ROUNDUP($B$14,0),1-SUM($D$18:F18),0)) -> 0.2 | H18: =IF(H$19<=ROUNDDOWN($B$14,0),(ROUNDDOWN($B$14,0)/$B$14)/ROUNDDOWN($B$14,0),IF(H$19=ROUNDUP($B$14,0),1-SUM($D$18:G18),0)) -> 0 | I18: =IF(I$19<=ROUNDDOWN($B$14,0),(ROUNDDOWN($B$14,0)/$B$14)/ROUNDDOWN($B$14,0),IF(I$19=ROUNDUP($B$14,0),1-SUM($D$18:H18),0)) -> 0 | J18: =IF(J$19<=ROUNDDOWN($B$14,0),(ROUNDDOWN($B$14,0)/$B$14)/ROUNDDOWN($B$14,0),IF(J$19=ROUNDUP($B$14,0),1-SUM($D$18:I18),0)) -> 0 | K18: =IF(K$19<=ROUNDDOWN($B$14,0),(ROUNDDOWN($B$14,0)/$B$14)/ROUNDDOWN($B$14,0),IF(K$19=ROUNDUP($B$14,0),1-SUM($D$18:J18),0)) -> 0 | L18: =IF(L$19<=ROUNDDOWN($B$14,0),(ROUNDDOWN($B$14,0)/$B$14)/ROUNDDOWN($B$14,0),IF(L$19=ROUNDUP($B$14,0),1-SUM($D$18:K18),0)) -> 0 | M18: =IF(M$19<=ROUNDDOWN($B$14,0),(ROUNDDOWN($B$14,0)/$B$14)/ROUNDDOWN($B$14,0),IF(M$19=ROUNDUP($B$14,0),1-SUM($D$18:L18),0)) -> 0
A19: Polozka | B19: Vlastnik polozky | C19: DPH | D19: PV | E19: 1 | F19: 2 | G19: 3 | H19: 4 | I19: 5 | J19: 6 | K19: 7 | L19: 8 | M19: 9 | N19: 10 | O19: 11 | P19: 12 | Q19: 13 | R19: 14 | S19: 15 | T19: 16 | U19: 17 | V19: 18 | W19: 19 | X19: 20 | Y19: 21 | Z19: 22 | AA19: 23 | AB19: 24 | AC19: 25 | AD19: 26 | AE19: 27 | AF19: 28 | AG19: 29 | AH19: 30 | AI19: 31 | AJ19: 32 | AK19: 33 | AL19: 34
A20: Naklady bez DPH
A21: CAPEX vystavba | B21: BOB | C21: TRUE | D21: =E21+NPV($K$5,F21:AK21) -> -12970075 | E21: =$B$8*E$18 -> -5351095.9 | F21: =$B$8*F$18 -> -5351095.9 | G21: =$B$8*G$18 -> -2675548 | H21: =$B$8*H$18 -> 0 | I21: =$B$8*I$18 -> 0 | J21: =$B$8*J$18 -> 0 | K21: =$B$8*K$18 -> 0 | L21: =$B$8*L$18 -> 0 | ... AL21: =$B$8*AL$18 -> 0
A22: CAPEX obnova | B22: HMBA | C22: FALSE | D22: =E22+NPV($K$5,F22:AK22) -> -1095557.1 | E22: =IF(E$19<($K$11+ROUNDUP($B$14,0)),0,IF(MOD(E$19-ROUNDUP($B$14,0),$K$11)=0,$B$6*$K$12*POWER(1+$B$13,E$19-ROUNDUP(E19,0)),0)) -> 0 | F22: =IF(F$19<($K$11+ROUNDUP($B$14,0)),0,IF(MOD(F$19-ROUNDUP($B$14,0),$K$11)=0,$B$6*$K$12*POWER(1+$B$13,F$19-ROUNDUP(F19,0)),0)) -> 0 | G22: =IF(G$19<($K$11+ROUNDUP($B$14,0)),0,IF(MOD(G$19-ROUNDUP($B$14,0),$K$11)=0,$B$6*$K$12*POWER(1+$B$13,G$19-ROUNDUP(G19,0)),0)) -> 0 | H22: =IF(H$19<($K$11+ROUNDUP($B$14,0)),0,IF(MOD(H$19-ROUNDUP($B$14,0),$K$11)=0,$B$6*$K$12*POWER(1+$B$13,H$19-ROUNDUP(H19,0)),0)) -> 0 | I22: =IF(I$19<($K$11+ROUNDUP($B$14,0)),0,IF(MOD(I$19-ROUNDUP($B$14,0),$K$11)=0,$B$6*$K$12*POWER(1+$B$13,I$19-ROUNDUP(I19,0)),0)) -> 0 | J22: =IF(J$19<($K$11+ROUNDUP($B$14,0)),0,IF(MOD(J$19-ROUNDUP($B$14,0),$K$11)=0,$B$6*$K$12*POWER(1+$B$13,J$19-ROUNDUP(J19,0)),0)) -> 0 | K22: =IF(K$19<($K$11+ROUNDUP($B$14,0)),0,IF(MOD(K$19-ROUNDUP($B$14,0),$K$11)=0,$B$6*$K$12*POWER(1+$B$13,K$19-ROUNDUP(K19,0)),0)) -> 0 | L22: =IF(L$19<($K$11+ROUNDUP($B$14,0)),0,IF(MOD(L$19-ROUNDUP($B$14,0),$K$11)=0,$B$6*$K$12*POWER(1+$B$13,L$19-ROUNDUP(L19,0)),0)) -> 0 | ... AL22: =IF(AL$19<($K$11+ROUNDUP($B$14,0)),0,IF(MOD(AL$19-ROUNDUP($B$14,0),$K$11)=0,$B$6*$K$12*POWER(1+$B$13,AL$19-ROUNDUP(AL19,0)),0)) -> 0
A24: DPH na vstupe | B24: BOB | D24: =E24+NPV($K$5,F24:AK24) -> -2983117.2 | E24: =SUMIFS(E$21:E$23,$C$21:$C$23,TRUE)*$B$12 -> -1230752.1 | F24: =SUMIFS(F$21:F$23,$C$21:$C$23,TRUE)*$B$12 -> -1230752.1 | G24: =SUMIFS(G$21:G$23,$C$21:$C$23,TRUE)*$B$12 -> -615376.03 | H24: =SUMIFS(H$21:H$23,$C$21:$C$23,TRUE)*$B$12 -> 0 | I24: =SUMIFS(I$21:I$23,$C$21:$C$23,TRUE)*$B$12 -> 0 | J24: =SUMIFS(J$21:J$23,$C$21:$C$23,TRUE)*$B$12 -> 0 | K24: =SUMIFS(K$21:K$23,$C$21:$C$23,TRUE)*$B$12 -> 0 | L24: =SUMIFS(L$21:L$23,$C$21:$C$23,TRUE)*$B$12 -> 0 | ... AL24: =SUMIFS(AL$21:AL$23,$C$21:$C$23,TRUE)*$B$12 -> 0
A26: Najomne a fond oprav
A27: Prijem z najomneho byty | B27: HMBA | C27: FALSE | D27: =E27+NPV($K$5,F27:AK27) -> 9205370.3 | E27: =IF(E19>$B$14,$H$13*POWER(1+$B$13,E$19-$B$14),0)*(1-(($B$14-ROUNDDOWN($B$14,0))*IF(E$19=ROUNDUP($B$14,0),1,0))) -> 0 | F27: =IF(F19>$B$14,$H$13*POWER(1+$B$13,F$19-$B$14),0)*(1-(($B$14-ROUNDDOWN($B$14,0))*IF(F$19=ROUNDUP($B$14,0),1,0))) -> 0 | G27: =IF(G19>$B$14,$H$13*POWER(1+$B$13,G$19-$B$14),0)*(1-(($B$14-ROUNDDOWN($B$14,0))*IF(G$19=ROUNDUP($B$14,0),1,0))) -> 216279.89 | H27: =IF(H19>$B$14,$H$13*POWER(1+$B$13,H$19-$B$14),0)*(1-(($B$14-ROUNDDOWN($B$14,0))*IF(H$19=ROUNDUP($B$14,0),1,0))) -> 441210.97 | I27: =IF(I19>$B$14,$H$13*POWER(1+$B$13,I$19-$B$14),0)*(1-(($B$14-ROUNDDOWN($B$14,0))*IF(I$19=ROUNDUP($B$14,0),1,0))) -> 450035.19 | J27: =IF(J19>$B$14,$H$13*POWER(1+$B$13,J$19-$B$14),0)*(1-(($B$14-ROUNDDOWN($B$14,0))*IF(J$19=ROUNDUP($B$14,0),1,0))) -> 459035.9 | K27: =IF(K19>$B$14,$H$13*POWER(1+$B$13,K$19-$B$14),0)*(1-(($B$14-ROUNDDOWN($B$14,0))*IF(K$19=ROUNDUP($B$14,0),1,0))) -> 468216.61 | L27: =IF(L19>$B$14,$H$13*POWER(1+$B$13,L$19-$B$14),0)*(1-(($B$14-ROUNDDOWN($B$14,0))*IF(L$19=ROUNDUP($B$14,0),1,0))) -> 477580.95 | ... AL27: =IF(AL19>$B$14,$H$13*POWER(1+$B$13,AL$19-$B$14),0)*(1-(($B$14-ROUNDDOWN($B$14,0))*IF(AL$19=ROUNDUP($B$14,0),1,0))) -> 799192.61
A28: Prijem z najomneho nebyty | B28: HMBA | C28: FALSE | D28: =E28+NPV($K$5,F28:AK28) -> 1737057 | E28: =IF(E19>$B$14,$H$14*POWER(1+$B$13,E$19-$B$14),0)*(1-(($B$14-ROUNDDOWN($B$14,0))*IF(E$19=ROUNDUP($B$14,0),1,0))) -> 0 | F28: =IF(F19>$B$14,$H$14*POWER(1+$B$13,F$19-$B$14),0)*(1-(($B$14-ROUNDDOWN($B$14,0))*IF(F$19=ROUNDUP($B$14,0),1,0))) -> 0 | G28: =IF(G19>$B$14,$H$14*POWER(1+$B$13,G$19-$B$14),0)*(1-(($B$14-ROUNDDOWN($B$14,0))*IF(G$19=ROUNDUP($B$14,0),1,0))) -> 40812.099 | H28: =IF(H19>$B$14,$H$14*POWER(1+$B$13,H$19-$B$14),0)*(1-(($B$14-ROUNDDOWN($B$14,0))*IF(H$19=ROUNDUP($B$14,0),1,0))) -> 83256.683 | I28: =IF(I19>$B$14,$H$14*POWER(1+$B$13,I$19-$B$14),0)*(1-(($B$14-ROUNDDOWN($B$14,0))*IF(I$19=ROUNDUP($B$14,0),1,0))) -> 84921.817 | J28: =IF(J19>$B$14,$H$14*POWER(1+$B$13,J$19-$B$14),0)*(1-(($B$14-ROUNDDOWN($B$14,0))*IF(J$19=ROUNDUP($B$14,0),1,0))) -> 86620.253 | K28: =IF(K19>$B$14,$H$14*POWER(1+$B$13,K$19-$B$14),0)*(1-(($B$14-ROUNDDOWN($B$14,0))*IF(K$19=ROUNDUP($B$14,0),1,0))) -> 88352.658 | L28: =IF(L19>$B$14,$H$14*POWER(1+$B$13,L$19-$B$14),0)*(1-(($B$14-ROUNDDOWN($B$14,0))*IF(L$19=ROUNDUP($B$14,0),1,0))) -> 90119.711 | ... AL28: =IF(AL19>$B$14,$H$14*POWER(1+$B$13,AL$19-$B$14),0)*(1-(($B$14-ROUNDDOWN($B$14,0))*IF(AL$19=ROUNDUP($B$14,0),1,0))) -> 150807.96
A29: Tvorba fondu oprav na CAPEX | C29: FALSE | D29: =E29+NPV($K$5,F29:AK29) -> -2529379.8 | E29: =IF(E27>0,$B$6*$K$13*POWER(1+$B$13,E$19-$B$14),0) -> 0 | F29: =IF(F27>0,$B$6*$K$13*POWER(1+$B$13,F$19-$B$14),0) -> 0 | G29: =IF(G27>0,$B$6*$K$13*POWER(1+$B$13,G$19-$B$14),0) -> -116328.46 | H29: =IF(H27>0,$B$6*$K$13*POWER(1+$B$13,H$19-$B$14),0) -> -118655.03 | I29: =IF(I27>0,$B$6*$K$13*POWER(1+$B$13,I$19-$B$14),0) -> -121028.13 | J29: =IF(J27>0,$B$6*$K$13*POWER(1+$B$13,J$19-$B$14),0) -> -123448.69 | K29: =IF(K27>0,$B$6*$K$13*POWER(1+$B$13,K$19-$B$14),0) -> -125917.67 | L29: =IF(L27>0,$B$6*$K$13*POWER(1+$B$13,L$19-$B$14),0) -> -128436.02 | ... AL29: =IF(AL27>0,$B$6*$K$13*POWER(1+$B$13,AL$19-$B$14),0) -> -214927.16
A30: Cerpanie fondu oprav na CAPEX | C30: FALSE | D30: =E30+NPV($K$5,F30:AK30) -> 1095557.1 | E30: =-E22 -> 0 | F30: =-F22 -> 0 | G30: =-G22 -> 0 | H30: =-H22 -> 0 | I30: =-I22 -> 0 | J30: =-J22 -> 0 | K30: =-K22 -> 0 | L30: =-L22 -> 0 | ... AL30: =-AL22 -> 0
A31: Zostatok fondu oprav na CAPEX | E31: 0 | F31: =E31-F29-F30 -> 0 | G31: =F31-G29-G30 -> 116328.46 | H31: =G31-H29-H30 -> 234983.49 | I31: =H31-I29-I30 -> 356011.62 | J31: =I31-J29-J30 -> 479460.32 | K31: =J31-K29-K30 -> 605377.98 | L31: =K31-L29-L30 -> 733814 | M31: =L31-M29-M30 -> 864818.75 | ... AL31: =AK31-AL29-AL30 -> 2676669.3
A33: Financovanie
A34: Cerpanie komercneho uveru (bullet) | B34: BOB | C34: FALSE | D34: =E34+NPV($K$5,F34:AK34) -> 15953192 | E34: =IF(E18>0,-E21-E24,0) -> 6581848 | F34: =IF(F18>0,-F21-F24,0) -> 6581848 | G34: =IF(G18>0,-G21-G24,0) -> 3290924 | H34: =IF(H18>0,-H21-H24,0) -> 0 | I34: =IF(I18>0,-I21-I24,0) -> 0 | J34: =IF(J18>0,-J21-J24,0) -> 0 | K34: =IF(K18>0,-K21-K24,0) -> 0 | L34: =IF(L18>0,-L21-L24,0) -> 0 | ... AL34: =IF(AL18>0,-AL21-AL24,0) -> 0
A35: Dotacia SFRB | B35: HMBA | C35: FALSE | D35: =E35+NPV($K$5,F35:AK35) -> 3074711.5 | E35: =IF(E$19=ROUNDUP($B$14,0),$H$12*$H$7,0) -> 0 | F35: =IF(F$19=ROUNDUP($B$14,0),$H$12*$H$7,0) -> 0 | G35: =IF(G$19=ROUNDUP($B$14,0),$H$12*$H$7,0) -> 3325608 | H35: =IF(H$19=ROUNDUP($B$14,0),$H$12*$H$7,0) -> 0 | I35: =IF(I$19=ROUNDUP($B$14,0),$H$12*$H$7,0) -> 0 | J35: =IF(J$19=ROUNDUP($B$14,0),$H$12*$H$7,0) -> 0 | K35: =IF(K$19=ROUNDUP($B$14,0),$H$12*$H$7,0) -> 0 | L35: =IF(L$19=ROUNDUP($B$14,0),$H$12*$H$7,0) -> 0 | ... AL35: =IF(AL$19=ROUNDUP($B$14,0),$H$12*$H$7,0) -> 0
A36: Uver SFRB | B36: HMBA | C36: FALSE | D36: =E36+NPV($K$5,F36:AK36) -> 4612067.3 | E36: =IF(E$19=ROUNDUP($B$14,0),$H$12*(1-$H$7),0) -> 0 | F36: =IF(F$19=ROUNDUP($B$14,0),$H$12*(1-$H$7),0) -> 0 | G36: =IF(G$19=ROUNDUP($B$14,0),$H$12*(1-$H$7),0) -> 4988412 | H36: =IF(H$19=ROUNDUP($B$14,0),$H$12*(1-$H$7),0) -> 0 | I36: =IF(I$19=ROUNDUP($B$14,0),$H$12*(1-$H$7),0) -> 0 | J36: =IF(J$19=ROUNDUP($B$14,0),$H$12*(1-$H$7),0) -> 0 | K36: =IF(K$19=ROUNDUP($B$14,0),$H$12*(1-$H$7),0) -> 0 | L36: =IF(L$19=ROUNDUP($B$14,0),$H$12*(1-$H$7),0) -> 0 | ... AL36: =IF(AL$19=ROUNDUP($B$14,0),$H$12*(1-$H$7),0) -> 0
A37: Uver HMBA | B37: HMBA | C37: FALSE | D37: =E37+NPV($K$5,F37:AK37) -> 7660264.9 | E37: =IF(E$19=ROUNDUP($B$14,0),$N$12,0) -> 0 | F37: =IF(F$19=ROUNDUP($B$14,0),$N$12,0) -> 0 | G37: =IF(G$19=ROUNDUP($B$14,0),$N$12,0) -> 8285342.5 | H37: =IF(H$19=ROUNDUP($B$14,0),$N$12,0) -> 0 | I37: =IF(I$19=ROUNDUP($B$14,0),$N$12,0) -> 0 | J37: =IF(J$19=ROUNDUP($B$14,0),$N$12,0) -> 0 | K37: =IF(K$19=ROUNDUP($B$14,0),$N$12,0) -> 0 | L37: =IF(L$19=ROUNDUP($B$14,0),$N$12,0) -> 0 | ... AL37: =IF(AL$19=ROUNDUP($B$14,0),$N$12,0) -> 0
A38: Kupa bytov do vlastnictva HMBA | B38: HMBA | C38: FALSE | D38: =E38+NPV($K$5,F38:AK38) -> -15347044 | E38: =IF(E$19=ROUNDUP($B$14,0),-$H$12-$N$12,0) -> 0 | F38: =IF(F$19=ROUNDUP($B$14,0),-$H$12-$N$12,0) -> 0 | G38: =IF(G$19=ROUNDUP($B$14,0),-$H$12-$N$12,0) -> -16599362 | H38: =IF(H$19=ROUNDUP($B$14,0),-$H$12-$N$12,0) -> 0 | I38: =IF(I$19=ROUNDUP($B$14,0),-$H$12-$N$12,0) -> 0 | J38: =IF(J$19=ROUNDUP($B$14,0),-$H$12-$N$12,0) -> 0 | K38: =IF(K$19=ROUNDUP($B$14,0),-$H$12-$N$12,0) -> 0 | L38: =IF(L$19=ROUNDUP($B$14,0),-$H$12-$N$12,0) -> 0 | ... AL38: =IF(AL$19=ROUNDUP($B$14,0),-$H$12-$N$12,0) -> 0
A39: Prijem z predaja bytov | B39: BOB | C39: TRUE | D39: =E39+NPV($K$5,F39:AK39) -> 14616232 | E39: =-E38/(1+$B$11) -> 0 | F39: =-F38/(1+$B$11) -> 0 | G39: =-G38/(1+$B$11) -> 15808917 | H39: =-H38/(1+$B$11) -> 0 | I39: =-I38/(1+$B$11) -> 0 | J39: =-J38/(1+$B$11) -> 0 | K39: =-K38/(1+$B$11) -> 0 | L39: =-L38/(1+$B$11) -> 0 | ... AL39: =-AL38/(1+$B$11) -> 0
A40: DPH na vystupe | B40: BOB | D40: =E40+NPV($K$5,F40:AK40) -> 730811.6 | E40: =SUMIFS(E$34:E$39,$C$34:$C$39,TRUE)*$B$11 -> 0 | F40: =SUMIFS(F$34:F$39,$C$34:$C$39,TRUE)*$B$11 -> 0 | G40: =SUMIFS(G$34:G$39,$C$34:$C$39,TRUE)*$B$11 -> 790445.83 | H40: =SUMIFS(H$34:H$39,$C$34:$C$39,TRUE)*$B$11 -> 0 | I40: =SUMIFS(I$34:I$39,$C$34:$C$39,TRUE)*$B$11 -> 0 | J40: =SUMIFS(J$34:J$39,$C$34:$C$39,TRUE)*$B$11 -> 0 | K40: =SUMIFS(K$34:K$39,$C$34:$C$39,TRUE)*$B$11 -> 0 | L40: =SUMIFS(L$34:L$39,$C$34:$C$39,TRUE)*$B$11 -> 0 | ... AL40: =SUMIFS(AL$34:AL$39,$C$34:$C$39,TRUE)*$B$11 -> 0
A42: Dlhova sluzba
A43: Kapitalizacia urokov komercneho uveru | B43: FALSE | C43: FALSE | E43: =E34*0.5*$K$7*IF(E18=0,0,1) -> 197455.44 | F43: =(SUM($E$34:E34)+F34*0.5)*$K$7*IF(F18=0,0,1) -> 592366.32 | G43: =(SUM($E$34:F34)+G34*0.5)*$K$7*IF(G18=0,0,1) -> 888549.48 | H43: =(SUM($E$34:G34)+H34*0.5)*$K$7*IF(H18=0,0,1) -> 0 | I43: =(SUM($E$34:H34)+I34*0.5)*$K$7*IF(I18=0,0,1) -> 0 | J43: =(SUM($E$34:I34)+J34*0.5)*$K$7*IF(J18=0,0,1) -> 0 | K43: =(SUM($E$34:J34)+K34*0.5)*$K$7*IF(K18=0,0,1) -> 0 | L43: =(SUM($E$34:K34)+L34*0.5)*$K$7*IF(L18=0,0,1) -> 0 | M43: =(SUM($E$34:L34)+M34*0.5)*$K$7*IF(M18=0,0,1) -> 0 | ... AL43: =(SUM($E$34:AK34)+AL34*0.5)*$K$7*IF(AL18=0,0,1) -> 0
A44: Splatka komercneho uveru | B44: BOB | C44: FALSE | D44: =E44+NPV($K$5,F44:AK44) -> -16764970 | E44: =-IF(E19=ROUNDUP($B$14,0),SUM($E$34:$AL$34,$E$43:$AL$43),0) -> 0 | F44: =-IF(F19=ROUNDUP($B$14,0),SUM($E$34:$AL$34,$E$43:$AL$43),0) -> 0 | G44: =-IF(G19=ROUNDUP($B$14,0),SUM($E$34:$AL$34,$E$43:$AL$43),0) -> -18132991 | H44: =-IF(H19=ROUNDUP($B$14,0),SUM($E$34:$AL$34,$E$43:$AL$43),0) -> 0 | I44: =-IF(I19=ROUNDUP($B$14,0),SUM($E$34:$AL$34,$E$43:$AL$43),0) -> 0 | J44: =-IF(J19=ROUNDUP($B$14,0),SUM($E$34:$AL$34,$E$43:$AL$43),0) -> 0 | K44: =-IF(K19=ROUNDUP($B$14,0),SUM($E$34:$AL$34,$E$43:$AL$43),0) -> 0 | L44: =-IF(L19=ROUNDUP($B$14,0),SUM($E$34:$AL$34,$E$43:$AL$43),0) -> 0 | ... AL44: =-IF(AL19=ROUNDUP($B$14,0),SUM($E$34:$AL$34,$E$43:$AL$43),0) -> 0
